2018-10-20 21:53:25,243 ERROR: Exception on /add_prospect [GET] [in /home/gene/.local/lib/python2.7/site-packages/flask/app.py:1761]
Traceback (most recent call last):
  File "/home/gene/.local/lib/python2.7/site-packages/flask/app.py", line 2292, in wsgi_app
    response = self.full_dispatch_request()
  File "/home/gene/.local/lib/python2.7/site-packages/flask/app.py", line 1815, in full_dispatch_request
    rv = self.handle_user_exception(e)
  File "/home/gene/.local/lib/python2.7/site-packages/flask/app.py", line 1718, in handle_user_exception
    reraise(exc_type, exc_value, tb)
  File "/home/gene/.local/lib/python2.7/site-packages/flask/app.py", line 1813, in full_dispatch_request
    rv = self.dispatch_request()
  File "/home/gene/.local/lib/python2.7/site-packages/flask/app.py", line 1799, in dispatch_request
    return self.view_functions[rule.endpoint](**req.view_args)
  File "/home/gene/.local/lib/python2.7/site-packages/flask_login/utils.py", line 261, in decorated_view
    return func(*args, **kwargs)
  File "/mnt/c/Users/Tyhebrewsaurus Rex/CRM/app/routes.py", line 52, in add_prospect
    form = AddProspectForm()
  File "/home/gene/.local/lib/python2.7/site-packages/wtforms/form.py", line 212, in __call__
    return type.__call__(cls, *args, **kwargs)
  File "/home/gene/.local/lib/python2.7/site-packages/flask_wtf/form.py", line 88, in __init__
    super(FlaskForm, self).__init__(formdata=formdata, **kwargs)
  File "/home/gene/.local/lib/python2.7/site-packages/wtforms/form.py", line 272, in __init__
    super(Form, self).__init__(self._unbound_fields, meta=meta_obj, prefix=prefix)
  File "/home/gene/.local/lib/python2.7/site-packages/wtforms/form.py", line 52, in __init__
    field = meta.bind_field(self, unbound_field, options)
  File "/home/gene/.local/lib/python2.7/site-packages/wtforms/meta.py", line 27, in bind_field
    return unbound_field.bind(form=form, **options)
  File "/home/gene/.local/lib/python2.7/site-packages/wtforms/fields/core.py", line 353, in bind
    return self.field_class(*self.args, **kw)
TypeError: __init__() got an unexpected keyword argument 'maxlength'
2018-10-20 21:54:19,178 INFO: ReDefined CRM Startup [in /mnt/c/Users/Tyhebrewsaurus Rex/CRM/app/__init__.py:49]
