2018-12-18 20:40:23,464 ERROR: Exception on /hello_people.pdf [GET] [in /mnt/c/Users/GM/Desktop/CRM/venv/lib/python3.6/site-packages/flask/app.py:1761]
Traceback (most recent call last):
  File "/mnt/c/Users/GM/Desktop/CRM/venv/lib/python3.6/site-packages/flask/app.py", line 2292, in wsgi_app
    response = self.full_dispatch_request()
  File "/mnt/c/Users/GM/Desktop/CRM/venv/lib/python3.6/site-packages/flask/app.py", line 1815, in full_dispatch_request
    rv = self.handle_user_exception(e)
  File "/mnt/c/Users/GM/Desktop/CRM/venv/lib/python3.6/site-packages/flask/app.py", line 1718, in handle_user_exception
    reraise(exc_type, exc_value, tb)
  File "/mnt/c/Users/GM/Desktop/CRM/venv/lib/python3.6/site-packages/flask/_compat.py", line 35, in reraise
    raise value
  File "/mnt/c/Users/GM/Desktop/CRM/venv/lib/python3.6/site-packages/flask/app.py", line 1813, in full_dispatch_request
    rv = self.dispatch_request()
  File "/mnt/c/Users/GM/Desktop/CRM/venv/lib/python3.6/site-packages/flask/app.py", line 1799, in dispatch_request
    return self.view_functions[rule.endpoint](**req.view_args)
TypeError: hello_pdf() missing 2 required positional arguments: 'fname' and 'lname'
2018-12-18 20:41:32,259 INFO: ReDefined CRM Startup [in /mnt/c/Users/GM/Desktop/CRM/app/__init__.py:53]
2018-12-18 20:41:37,805 ERROR: Exception on /hello_people.pdf [GET] [in /mnt/c/Users/GM/Desktop/CRM/venv/lib/python3.6/site-packages/flask/app.py:1761]
Traceback (most recent call last):
  File "/mnt/c/Users/GM/Desktop/CRM/venv/lib/python3.6/site-packages/flask/app.py", line 2292, in wsgi_app
    response = self.full_dispatch_request()
  File "/mnt/c/Users/GM/Desktop/CRM/venv/lib/python3.6/site-packages/flask/app.py", line 1815, in full_dispatch_request
    rv = self.handle_user_exception(e)
  File "/mnt/c/Users/GM/Desktop/CRM/venv/lib/python3.6/site-packages/flask/app.py", line 1718, in handle_user_exception
    reraise(exc_type, exc_value, tb)
  File "/mnt/c/Users/GM/Desktop/CRM/venv/lib/python3.6/site-packages/flask/_compat.py", line 35, in reraise
    raise value
  File "/mnt/c/Users/GM/Desktop/CRM/venv/lib/python3.6/site-packages/flask/app.py", line 1813, in full_dispatch_request
    rv = self.dispatch_request()
  File "/mnt/c/Users/GM/Desktop/CRM/venv/lib/python3.6/site-packages/flask/app.py", line 1799, in dispatch_request
    return self.view_functions[rule.endpoint](**req.view_args)
TypeError: hello_pdf() missing 2 required positional arguments: 'fname' and 'lname'
2018-12-18 20:43:04,089 INFO: ReDefined CRM Startup [in /mnt/c/Users/GM/Desktop/CRM/app/__init__.py:53]
2018-12-18 20:43:08,963 ERROR: Exception on /hello_people.pdf [GET] [in /mnt/c/Users/GM/Desktop/CRM/venv/lib/python3.6/site-packages/flask/app.py:1761]
Traceback (most recent call last):
  File "/mnt/c/Users/GM/Desktop/CRM/venv/lib/python3.6/site-packages/flask/app.py", line 2292, in wsgi_app
    response = self.full_dispatch_request()
  File "/mnt/c/Users/GM/Desktop/CRM/venv/lib/python3.6/site-packages/flask/app.py", line 1815, in full_dispatch_request
    rv = self.handle_user_exception(e)
  File "/mnt/c/Users/GM/Desktop/CRM/venv/lib/python3.6/site-packages/flask/app.py", line 1718, in handle_user_exception
    reraise(exc_type, exc_value, tb)
  File "/mnt/c/Users/GM/Desktop/CRM/venv/lib/python3.6/site-packages/flask/_compat.py", line 35, in reraise
    raise value
  File "/mnt/c/Users/GM/Desktop/CRM/venv/lib/python3.6/site-packages/flask/app.py", line 1813, in full_dispatch_request
    rv = self.dispatch_request()
  File "/mnt/c/Users/GM/Desktop/CRM/venv/lib/python3.6/site-packages/flask/app.py", line 1799, in dispatch_request
    return self.view_functions[rule.endpoint](**req.view_args)
TypeError: hello_pdf() missing 2 required positional arguments: 'fname' and 'lname'
2018-12-18 20:43:49,968 INFO: ReDefined CRM Startup [in /mnt/c/Users/GM/Desktop/CRM/app/__init__.py:53]
2018-12-18 20:44:23,534 INFO: ReDefined CRM Startup [in /mnt/c/Users/GM/Desktop/CRM/app/__init__.py:53]
