2018-10-25 20:36:21,904 ERROR: Exception on /view_prospect/1 [GET] [in /mnt/c/Users/GM/Desktop/CRM/venv/lib/python3.6/site-packages/flask/app.py:1761]
Traceback (most recent call last):
  File "/mnt/c/Users/GM/Desktop/CRM/venv/lib/python3.6/site-packages/flask/app.py", line 2292, in wsgi_app
    response = self.full_dispatch_request()
  File "/mnt/c/Users/GM/Desktop/CRM/venv/lib/python3.6/site-packages/flask/app.py", line 1815, in full_dispatch_request
    rv = self.handle_user_exception(e)
  File "/mnt/c/Users/GM/Desktop/CRM/venv/lib/python3.6/site-packages/flask/app.py", line 1718, in handle_user_exception
    reraise(exc_type, exc_value, tb)
  File "/mnt/c/Users/GM/Desktop/CRM/venv/lib/python3.6/site-packages/flask/_compat.py", line 35, in reraise
    raise value
  File "/mnt/c/Users/GM/Desktop/CRM/venv/lib/python3.6/site-packages/flask/app.py", line 1813, in full_dispatch_request
    rv = self.dispatch_request()
  File "/mnt/c/Users/GM/Desktop/CRM/venv/lib/python3.6/site-packages/flask/app.py", line 1799, in dispatch_request
    return self.view_functions[rule.endpoint](**req.view_args)
  File "/mnt/c/Users/GM/Desktop/CRM/venv/lib/python3.6/site-packages/flask_login/utils.py", line 261, in decorated_view
    return func(*args, **kwargs)
  File "/mnt/c/Users/GM/Desktop/CRM/app/routes.py", line 36, in view_prospect
    form.first_name.data = "Test this out"
AttributeError: 'ModifyProspectForm' object has no attribute 'first_name'
2018-10-25 20:36:50,944 INFO: ReDefined CRM Startup [in /mnt/c/Users/GM/Desktop/CRM/app/__init__.py:49]
2018-10-25 20:38:00,795 INFO: ReDefined CRM Startup [in /mnt/c/Users/GM/Desktop/CRM/app/__init__.py:49]
2018-10-25 20:38:41,538 INFO: ReDefined CRM Startup [in /mnt/c/Users/GM/Desktop/CRM/app/__init__.py:49]
2018-10-25 20:39:36,551 INFO: ReDefined CRM Startup [in /mnt/c/Users/GM/Desktop/CRM/app/__init__.py:49]
2018-10-25 20:39:58,052 INFO: ReDefined CRM Startup [in /mnt/c/Users/GM/Desktop/CRM/app/__init__.py:49]
2018-10-25 20:40:21,636 INFO: ReDefined CRM Startup [in /mnt/c/Users/GM/Desktop/CRM/app/__init__.py:49]
2018-10-25 20:41:44,349 INFO: ReDefined CRM Startup [in /mnt/c/Users/GM/Desktop/CRM/app/__init__.py:49]
2018-10-26 20:44:16,707 INFO: ReDefined CRM Startup [in /mnt/c/Users/Tyhebrewsaurus Rex/CRM/app/__init__.py:49]
2018-10-26 20:44:28,531 INFO: ReDefined CRM Startup [in /mnt/c/Users/Tyhebrewsaurus Rex/CRM/app/__init__.py:49]
2018-10-26 21:31:41,207 INFO: ReDefined CRM Startup [in /mnt/c/Users/Tyhebrewsaurus Rex/CRM/app/__init__.py:49]
2018-10-26 21:32:48,878 INFO: ReDefined CRM Startup [in /mnt/c/Users/Tyhebrewsaurus Rex/CRM/app/__init__.py:49]
2018-10-26 21:33:32,854 INFO: ReDefined CRM Startup [in app/__init__.py:49]
2018-10-26 21:40:01,737 INFO: ReDefined CRM Startup [in /mnt/c/Users/Tyhebrewsaurus Rex/CRM/app/__init__.py:49]
2018-10-26 21:41:36,512 INFO: ReDefined CRM Startup [in /mnt/c/Users/Tyhebrewsaurus Rex/CRM/app/__init__.py:49]
2018-10-26 21:49:35,374 INFO: ReDefined CRM Startup [in /mnt/c/Users/Tyhebrewsaurus Rex/CRM/app/__init__.py:49]
2018-10-26 21:52:38,109 INFO: ReDefined CRM Startup [in /mnt/c/Users/Tyhebrewsaurus Rex/CRM/app/__init__.py:49]
2018-10-26 21:53:29,736 INFO: ReDefined CRM Startup [in /mnt/c/Users/Tyhebrewsaurus Rex/CRM/app/__init__.py:49]
2018-10-26 21:54:07,587 INFO: ReDefined CRM Startup [in /mnt/c/Users/Tyhebrewsaurus Rex/CRM/app/__init__.py:49]
2018-10-26 21:55:03,512 INFO: ReDefined CRM Startup [in /mnt/c/Users/Tyhebrewsaurus Rex/CRM/app/__init__.py:49]
2018-10-26 21:58:06,987 INFO: ReDefined CRM Startup [in /mnt/c/Users/Tyhebrewsaurus Rex/CRM/app/__init__.py:49]
2018-10-26 22:03:32,989 INFO: ReDefined CRM Startup [in /mnt/c/Users/Tyhebrewsaurus Rex/CRM/app/__init__.py:49]
2018-10-26 22:18:19,933 INFO: ReDefined CRM Startup [in /mnt/c/Users/Tyhebrewsaurus Rex/CRM/app/__init__.py:49]
2018-10-26 22:18:44,674 INFO: ReDefined CRM Startup [in /mnt/c/Users/Tyhebrewsaurus Rex/CRM/app/__init__.py:49]
2018-10-26 22:18:54,393 ERROR: Exception on /view_client/1 [POST] [in /home/gene/.local/lib/python2.7/site-packages/flask/app.py:1761]
Traceback (most recent call last):
  File "/home/gene/.local/lib/python2.7/site-packages/flask/app.py", line 2292, in wsgi_app
    response = self.full_dispatch_request()
  File "/home/gene/.local/lib/python2.7/site-packages/flask/app.py", line 1815, in full_dispatch_request
    rv = self.handle_user_exception(e)
  File "/home/gene/.local/lib/python2.7/site-packages/flask/app.py", line 1718, in handle_user_exception
    reraise(exc_type, exc_value, tb)
  File "/home/gene/.local/lib/python2.7/site-packages/flask/app.py", line 1813, in full_dispatch_request
    rv = self.dispatch_request()
  File "/home/gene/.local/lib/python2.7/site-packages/flask/app.py", line 1799, in dispatch_request
    return self.view_functions[rule.endpoint](**req.view_args)
  File "/home/gene/.local/lib/python2.7/site-packages/flask_login/utils.py", line 261, in decorated_view
    return func(*args, **kwargs)
  File "/mnt/c/Users/Tyhebrewsaurus Rex/CRM/app/routes.py", line 58, in view_client
    return redirect(url_for('clients'))
  File "/home/gene/.local/lib/python2.7/site-packages/flask/helpers.py", line 356, in url_for
    return appctx.app.handle_url_build_error(error, endpoint, values)
  File "/home/gene/.local/lib/python2.7/site-packages/flask/app.py", line 2061, in handle_url_build_error
    reraise(exc_type, exc_value, tb)
  File "/home/gene/.local/lib/python2.7/site-packages/flask/helpers.py", line 345, in url_for
    force_external=external)
  File "/home/gene/.local/lib/python2.7/site-packages/werkzeug/routing.py", line 1776, in build
    raise BuildError(endpoint, values, method, self)
BuildError: Could not build url for endpoint 'clients'. Did you mean 'add_client' instead?
2018-10-26 22:21:46,875 INFO: ReDefined CRM Startup [in /mnt/c/Users/Tyhebrewsaurus Rex/CRM/app/__init__.py:49]
