2019-01-23 19:08:16,390 INFO: ReDefined CRM Startup [in /home/gene/Desktop/CRM/app/__init__.py:53]
2019-01-23 19:18:44,035 INFO: ReDefined CRM Startup [in /home/gene/Desktop/CRM/app/__init__.py:53]
2019-01-23 19:21:18,137 INFO: ReDefined CRM Startup [in /home/gene/Desktop/CRM/app/__init__.py:53]
2019-01-23 19:22:31,870 INFO: ReDefined CRM Startup [in /home/gene/Desktop/CRM/app/__init__.py:53]
2019-01-23 19:22:52,384 INFO: ReDefined CRM Startup [in /home/gene/Desktop/CRM/app/__init__.py:53]
2019-01-23 19:36:59,126 INFO: ReDefined CRM Startup [in /home/gene/Desktop/CRM/app/__init__.py:53]
2019-01-23 19:39:32,794 INFO: ReDefined CRM Startup [in /home/gene/Desktop/CRM/app/__init__.py:53]
2019-01-23 19:40:14,591 INFO: ReDefined CRM Startup [in /home/gene/Desktop/CRM/app/__init__.py:53]
2019-01-23 19:41:35,015 INFO: ReDefined CRM Startup [in /home/gene/Desktop/CRM/app/__init__.py:53]
2019-01-23 19:42:14,646 INFO: ReDefined CRM Startup [in /home/gene/Desktop/CRM/app/__init__.py:53]
2019-01-23 19:42:35,645 INFO: ReDefined CRM Startup [in /home/gene/Desktop/CRM/app/__init__.py:53]
2019-01-23 19:44:35,156 INFO: ReDefined CRM Startup [in /home/gene/Desktop/CRM/app/__init__.py:53]
2019-01-23 19:45:21,684 INFO: ReDefined CRM Startup [in /home/gene/Desktop/CRM/app/__init__.py:53]
2019-01-23 19:50:00,509 INFO: ReDefined CRM Startup [in /home/gene/Desktop/CRM/app/__init__.py:53]
2019-01-23 20:12:49,384 INFO: ReDefined CRM Startup [in /home/gene/Desktop/CRM/app/__init__.py:53]
2019-01-23 20:14:19,674 INFO: ReDefined CRM Startup [in /home/gene/Desktop/CRM/app/__init__.py:53]
2019-01-23 20:14:43,724 ERROR: Exception on /hello_Avi_Dyno.pdf [GET] [in /home/gene/.local/lib/python3.6/site-packages/flask/app.py:1761]
Traceback (most recent call last):
  File "/home/gene/.local/lib/python3.6/site-packages/flask/app.py", line 2292, in wsgi_app
    response = self.full_dispatch_request()
  File "/home/gene/.local/lib/python3.6/site-packages/flask/app.py", line 1815, in full_dispatch_request
    rv = self.handle_user_exception(e)
  File "/home/gene/.local/lib/python3.6/site-packages/flask/app.py", line 1718, in handle_user_exception
    reraise(exc_type, exc_value, tb)
  File "/home/gene/.local/lib/python3.6/site-packages/flask/_compat.py", line 35, in reraise
    raise value
  File "/home/gene/.local/lib/python3.6/site-packages/flask/app.py", line 1813, in full_dispatch_request
    rv = self.dispatch_request()
  File "/home/gene/.local/lib/python3.6/site-packages/flask/app.py", line 1799, in dispatch_request
    return self.view_functions[rule.endpoint](**req.view_args)
  File "/home/gene/.local/lib/python3.6/site-packages/flask_login/utils.py", line 261, in decorated_view
    return func(*args, **kwargs)
  File "/home/gene/Desktop/CRM/app/routes.py", line 194, in hello_pdf
    people_street_number=select_people.street_number, people_street_name=select_people.street_name,
AttributeError: 'People' object has no attribute 'street_number'
2019-01-23 20:15:43,481 INFO: ReDefined CRM Startup [in /home/gene/Desktop/CRM/app/__init__.py:53]
2019-01-23 20:15:48,334 ERROR: Exception on /hello_Avi_Dyno.pdf [GET] [in /home/gene/.local/lib/python3.6/site-packages/flask/app.py:1761]
Traceback (most recent call last):
  File "/home/gene/.local/lib/python3.6/site-packages/flask/app.py", line 2292, in wsgi_app
    response = self.full_dispatch_request()
  File "/home/gene/.local/lib/python3.6/site-packages/flask/app.py", line 1815, in full_dispatch_request
    rv = self.handle_user_exception(e)
  File "/home/gene/.local/lib/python3.6/site-packages/flask/app.py", line 1718, in handle_user_exception
    reraise(exc_type, exc_value, tb)
  File "/home/gene/.local/lib/python3.6/site-packages/flask/_compat.py", line 35, in reraise
    raise value
  File "/home/gene/.local/lib/python3.6/site-packages/flask/app.py", line 1813, in full_dispatch_request
    rv = self.dispatch_request()
  File "/home/gene/.local/lib/python3.6/site-packages/flask/app.py", line 1799, in dispatch_request
    return self.view_functions[rule.endpoint](**req.view_args)
  File "/home/gene/.local/lib/python3.6/site-packages/flask_login/utils.py", line 261, in decorated_view
    return func(*args, **kwargs)
  File "/home/gene/Desktop/CRM/app/routes.py", line 194, in hello_pdf
    people_street_number=select_people.street_number, people_street_name=select_people.street_name,
AttributeError: 'People' object has no attribute 'street_number'
2019-01-23 20:16:42,522 INFO: ReDefined CRM Startup [in /home/gene/Desktop/CRM/app/__init__.py:53]
2019-01-23 20:17:13,604 INFO: ReDefined CRM Startup [in /home/gene/Desktop/CRM/app/__init__.py:53]
2019-01-24 17:33:30,242 INFO: ReDefined CRM Startup [in /home/gene/Desktop/CRM/app/__init__.py:53]
2019-01-24 17:33:34,420 INFO: ReDefined CRM Startup [in /home/gene/Desktop/CRM/app/__init__.py:53]
2019-01-24 17:39:53,166 INFO: ReDefined CRM Startup [in /home/gene/Desktop/CRM/app/__init__.py:53]
2019-01-24 17:39:57,186 INFO: ReDefined CRM Startup [in /home/gene/Desktop/CRM/app/__init__.py:53]
2019-01-24 18:21:23,299 INFO: ReDefined CRM Startup [in /home/gene/Desktop/CRM/app/__init__.py:53]
2019-01-24 18:24:53,381 INFO: ReDefined CRM Startup [in /home/gene/Desktop/CRM/app/__init__.py:53]
2019-01-24 18:31:28,012 INFO: ReDefined CRM Startup [in /home/gene/Desktop/CRM/app/__init__.py:53]
2019-01-24 18:39:53,003 INFO: ReDefined CRM Startup [in /home/gene/Desktop/CRM/app/__init__.py:53]
2019-01-24 18:40:01,480 ERROR: Exception on /convert_client/4 [POST] [in /home/gene/.local/lib/python3.6/site-packages/flask/app.py:1761]
Traceback (most recent call last):
  File "/home/gene/.local/lib/python3.6/site-packages/flask/app.py", line 2292, in wsgi_app
    response = self.full_dispatch_request()
  File "/home/gene/.local/lib/python3.6/site-packages/flask/app.py", line 1815, in full_dispatch_request
    rv = self.handle_user_exception(e)
  File "/home/gene/.local/lib/python3.6/site-packages/flask/app.py", line 1718, in handle_user_exception
    reraise(exc_type, exc_value, tb)
  File "/home/gene/.local/lib/python3.6/site-packages/flask/_compat.py", line 35, in reraise
    raise value
  File "/home/gene/.local/lib/python3.6/site-packages/flask/app.py", line 1813, in full_dispatch_request
    rv = self.dispatch_request()
  File "/home/gene/.local/lib/python3.6/site-packages/flask/app.py", line 1799, in dispatch_request
    return self.view_functions[rule.endpoint](**req.view_args)
  File "/home/gene/.local/lib/python3.6/site-packages/flask_login/utils.py", line 261, in decorated_view
    return func(*args, **kwargs)
  File "/home/gene/Desktop/CRM/app/routes.py", line 116, in convert_client
    convert_cl(account_pk=user_account_pk, people_id=people_id)
  File "/home/gene/Desktop/CRM/app/queryfunc.py", line 31, in convert_cl
    add_sale = ClosedDeals(first_name=convert_cl.first_name, last_name=convert_cl.last_name,
NameError: name 'ClosedDeals' is not defined
2019-01-24 18:41:33,167 INFO: ReDefined CRM Startup [in /home/gene/Desktop/CRM/app/__init__.py:53]
2019-01-24 18:41:38,407 ERROR: Exception on /convert_client/4 [POST] [in /home/gene/.local/lib/python3.6/site-packages/flask/app.py:1761]
Traceback (most recent call last):
  File "/home/gene/.local/lib/python3.6/site-packages/flask/app.py", line 2292, in wsgi_app
    response = self.full_dispatch_request()
  File "/home/gene/.local/lib/python3.6/site-packages/flask/app.py", line 1815, in full_dispatch_request
    rv = self.handle_user_exception(e)
  File "/home/gene/.local/lib/python3.6/site-packages/flask/app.py", line 1718, in handle_user_exception
    reraise(exc_type, exc_value, tb)
  File "/home/gene/.local/lib/python3.6/site-packages/flask/_compat.py", line 35, in reraise
    raise value
  File "/home/gene/.local/lib/python3.6/site-packages/flask/app.py", line 1813, in full_dispatch_request
    rv = self.dispatch_request()
  File "/home/gene/.local/lib/python3.6/site-packages/flask/app.py", line 1799, in dispatch_request
    return self.view_functions[rule.endpoint](**req.view_args)
  File "/home/gene/.local/lib/python3.6/site-packages/flask_login/utils.py", line 261, in decorated_view
    return func(*args, **kwargs)
  File "/home/gene/Desktop/CRM/app/routes.py", line 117, in convert_client
    convert_cl(account_pk=user_account_pk, people_id=people_id)
  File "/home/gene/Desktop/CRM/app/queryfunc.py", line 31, in convert_cl
    add_sale = ClosedDeals(first_name=convert_cl.first_name, last_name=convert_cl.last_name,
NameError: name 'ClosedDeals' is not defined
2019-01-24 18:42:09,490 INFO: ReDefined CRM Startup [in /home/gene/Desktop/CRM/app/__init__.py:53]
2019-01-24 18:42:14,103 ERROR: Exception on /convert_client/4 [POST] [in /home/gene/.local/lib/python3.6/site-packages/flask/app.py:1761]
Traceback (most recent call last):
  File "/home/gene/.local/lib/python3.6/site-packages/flask/app.py", line 2292, in wsgi_app
    response = self.full_dispatch_request()
  File "/home/gene/.local/lib/python3.6/site-packages/flask/app.py", line 1815, in full_dispatch_request
    rv = self.handle_user_exception(e)
  File "/home/gene/.local/lib/python3.6/site-packages/flask/app.py", line 1718, in handle_user_exception
    reraise(exc_type, exc_value, tb)
  File "/home/gene/.local/lib/python3.6/site-packages/flask/_compat.py", line 35, in reraise
    raise value
  File "/home/gene/.local/lib/python3.6/site-packages/flask/app.py", line 1813, in full_dispatch_request
    rv = self.dispatch_request()
  File "/home/gene/.local/lib/python3.6/site-packages/flask/app.py", line 1799, in dispatch_request
    return self.view_functions[rule.endpoint](**req.view_args)
  File "/home/gene/.local/lib/python3.6/site-packages/flask_login/utils.py", line 261, in decorated_view
    return func(*args, **kwargs)
  File "/home/gene/Desktop/CRM/app/routes.py", line 117, in convert_client
    convert_cl(account_pk=user_account_pk, people_id=people_id)
  File "/home/gene/Desktop/CRM/app/queryfunc.py", line 34, in convert_cl
    user_account_pk=convert_cl.account_pk)
AttributeError: 'People' object has no attribute 'account_pk'
2019-01-24 18:43:31,393 INFO: ReDefined CRM Startup [in /home/gene/Desktop/CRM/app/__init__.py:53]
