2018-11-06 20:37:42,849 ERROR: Exception on /view_people/<people_id> [GET] [in /mnt/c/Users/GM/Desktop/CRM/venv/lib/python3.6/site-packages/flask/app.py:1761]
Traceback (most recent call last):
  File "/mnt/c/Users/GM/Desktop/CRM/venv/lib/python3.6/site-packages/flask/app.py", line 2292, in wsgi_app
    response = self.full_dispatch_request()
  File "/mnt/c/Users/GM/Desktop/CRM/venv/lib/python3.6/site-packages/flask/app.py", line 1815, in full_dispatch_request
    rv = self.handle_user_exception(e)
  File "/mnt/c/Users/GM/Desktop/CRM/venv/lib/python3.6/site-packages/flask/app.py", line 1718, in handle_user_exception
    reraise(exc_type, exc_value, tb)
  File "/mnt/c/Users/GM/Desktop/CRM/venv/lib/python3.6/site-packages/flask/_compat.py", line 35, in reraise
    raise value
  File "/mnt/c/Users/GM/Desktop/CRM/venv/lib/python3.6/site-packages/flask/app.py", line 1813, in full_dispatch_request
    rv = self.dispatch_request()
  File "/mnt/c/Users/GM/Desktop/CRM/venv/lib/python3.6/site-packages/flask/app.py", line 1799, in dispatch_request
    return self.view_functions[rule.endpoint](**req.view_args)
  File "/mnt/c/Users/GM/Desktop/CRM/venv/lib/python3.6/site-packages/flask_login/utils.py", line 261, in decorated_view
    return func(*args, **kwargs)
  File "/mnt/c/Users/GM/Desktop/CRM/app/routes.py", line 69, in view_people
    form = ModifyPeopleForm(modified_first_name=select_people.first_name, modified_last_name=select_people.last_name, modified_phone_cell=select_people.phone_cell, modified_notes=select_people.notes)
AttributeError: 'NoneType' object has no attribute 'first_name'
2018-11-06 20:41:55,603 INFO: ReDefined CRM Startup [in /mnt/c/Users/GM/Desktop/CRM/app/__init__.py:53]
