2019-01-25 15:35:41,763 ERROR: Exception on /view_people/2 [GET] [in /home/gene/.local/lib/python3.6/site-packages/flask/app.py:1761]
Traceback (most recent call last):
  File "/home/gene/.local/lib/python3.6/site-packages/flask/app.py", line 2292, in wsgi_app
    response = self.full_dispatch_request()
  File "/home/gene/.local/lib/python3.6/site-packages/flask/app.py", line 1815, in full_dispatch_request
    rv = self.handle_user_exception(e)
  File "/home/gene/.local/lib/python3.6/site-packages/flask/app.py", line 1718, in handle_user_exception
    reraise(exc_type, exc_value, tb)
  File "/home/gene/.local/lib/python3.6/site-packages/flask/_compat.py", line 35, in reraise
    raise value
  File "/home/gene/.local/lib/python3.6/site-packages/flask/app.py", line 1813, in full_dispatch_request
    rv = self.dispatch_request()
  File "/home/gene/.local/lib/python3.6/site-packages/flask/app.py", line 1799, in dispatch_request
    return self.view_functions[rule.endpoint](**req.view_args)
  File "/home/gene/.local/lib/python3.6/site-packages/flask_login/utils.py", line 261, in decorated_view
    return func(*args, **kwargs)
  File "/home/gene/Desktop/CRM/app/routes.py", line 97, in view_people
    return render_template('view_people.html', title = 'View Person', select_people=select_people, modify_form=modify_form, notes_form=notes_form, viewpnotes=pnotes)
NameError: name 'notes_form' is not defined
2019-01-25 15:36:08,096 INFO: ReDefined CRM Startup [in /home/gene/Desktop/CRM/app/__init__.py:53]
2019-01-25 15:36:10,198 ERROR: Exception on /view_people/2 [GET] [in /home/gene/.local/lib/python3.6/site-packages/flask/app.py:1761]
Traceback (most recent call last):
  File "/home/gene/.local/lib/python3.6/site-packages/flask/app.py", line 2292, in wsgi_app
    response = self.full_dispatch_request()
  File "/home/gene/.local/lib/python3.6/site-packages/flask/app.py", line 1815, in full_dispatch_request
    rv = self.handle_user_exception(e)
  File "/home/gene/.local/lib/python3.6/site-packages/flask/app.py", line 1718, in handle_user_exception
    reraise(exc_type, exc_value, tb)
  File "/home/gene/.local/lib/python3.6/site-packages/flask/_compat.py", line 35, in reraise
    raise value
  File "/home/gene/.local/lib/python3.6/site-packages/flask/app.py", line 1813, in full_dispatch_request
    rv = self.dispatch_request()
  File "/home/gene/.local/lib/python3.6/site-packages/flask/app.py", line 1799, in dispatch_request
    return self.view_functions[rule.endpoint](**req.view_args)
  File "/home/gene/.local/lib/python3.6/site-packages/flask_login/utils.py", line 261, in decorated_view
    return func(*args, **kwargs)
  File "/home/gene/Desktop/CRM/app/routes.py", line 97, in view_people
    return render_template('view_people.html', title = 'View Person', select_people=select_people, modify_form=modify_form, viewpnotes=pnotes)
  File "/home/gene/.local/lib/python3.6/site-packages/flask/templating.py", line 135, in render_template
    context, ctx.app)
  File "/home/gene/.local/lib/python3.6/site-packages/flask/templating.py", line 117, in _render
    rv = template.render(context)
  File "/home/gene/.local/lib/python3.6/site-packages/jinja2/asyncsupport.py", line 76, in render
    return original_render(self, *args, **kwargs)
  File "/home/gene/.local/lib/python3.6/site-packages/jinja2/environment.py", line 1008, in render
    return self.environment.handle_exception(exc_info, True)
  File "/home/gene/.local/lib/python3.6/site-packages/jinja2/environment.py", line 780, in handle_exception
    reraise(exc_type, exc_value, tb)
  File "/home/gene/.local/lib/python3.6/site-packages/jinja2/_compat.py", line 37, in reraise
    raise value.with_traceback(tb)
  File "/home/gene/Desktop/CRM/app/templates/view_people.html", line 2, in top-level template code
    {% import 'bootstrap/wtf.html' as wtf %}
  File "/home/gene/Desktop/CRM/app/templates/base.html", line 1, in top-level template code
    {% extends 'bootstrap/base.html' %}
  File "/home/gene/.local/lib/python3.6/site-packages/flask_bootstrap/templates/bootstrap/base.html", line 1, in top-level template code
    {% block doc -%}
  File "/home/gene/.local/lib/python3.6/site-packages/flask_bootstrap/templates/bootstrap/base.html", line 4, in block "doc"
    {%- block html %}
  File "/home/gene/.local/lib/python3.6/site-packages/flask_bootstrap/templates/bootstrap/base.html", line 20, in block "html"
    {% block body -%}
  File "/home/gene/.local/lib/python3.6/site-packages/flask_bootstrap/templates/bootstrap/base.html", line 23, in block "body"
    {% block content -%}
  File "/home/gene/Desktop/CRM/app/templates/base.html", line 67, in block "content"
    {% block app_content %}{% endblock %}
  File "/home/gene/Desktop/CRM/app/templates/view_people.html", line 21, in block "app_content"
    <a href="{{ url_for('people_notes', people_id=everyone.id) }}">View Client Notes</a>
  File "/home/gene/.local/lib/python3.6/site-packages/jinja2/environment.py", line 430, in getattr
    return getattr(obj, attribute)
jinja2.exceptions.UndefinedError: 'everyone' is undefined
2019-01-25 15:36:53,410 INFO: ReDefined CRM Startup [in /home/gene/Desktop/CRM/app/__init__.py:53]
2019-01-25 15:36:56,260 ERROR: Exception on /view_people/2 [GET] [in /home/gene/.local/lib/python3.6/site-packages/flask/app.py:1761]
Traceback (most recent call last):
  File "/home/gene/.local/lib/python3.6/site-packages/flask/app.py", line 2292, in wsgi_app
    response = self.full_dispatch_request()
  File "/home/gene/.local/lib/python3.6/site-packages/flask/app.py", line 1815, in full_dispatch_request
    rv = self.handle_user_exception(e)
  File "/home/gene/.local/lib/python3.6/site-packages/flask/app.py", line 1718, in handle_user_exception
    reraise(exc_type, exc_value, tb)
  File "/home/gene/.local/lib/python3.6/site-packages/flask/_compat.py", line 35, in reraise
    raise value
  File "/home/gene/.local/lib/python3.6/site-packages/flask/app.py", line 1813, in full_dispatch_request
    rv = self.dispatch_request()
  File "/home/gene/.local/lib/python3.6/site-packages/flask/app.py", line 1799, in dispatch_request
    return self.view_functions[rule.endpoint](**req.view_args)
  File "/home/gene/.local/lib/python3.6/site-packages/flask_login/utils.py", line 261, in decorated_view
    return func(*args, **kwargs)
  File "/home/gene/Desktop/CRM/app/routes.py", line 97, in view_people
    return render_template('view_people.html', title = 'View Person', select_people=select_people, modify_form=modify_form, viewpnotes=pnotes)
  File "/home/gene/.local/lib/python3.6/site-packages/flask/templating.py", line 135, in render_template
    context, ctx.app)
  File "/home/gene/.local/lib/python3.6/site-packages/flask/templating.py", line 117, in _render
    rv = template.render(context)
  File "/home/gene/.local/lib/python3.6/site-packages/jinja2/asyncsupport.py", line 76, in render
    return original_render(self, *args, **kwargs)
  File "/home/gene/.local/lib/python3.6/site-packages/jinja2/environment.py", line 1008, in render
    return self.environment.handle_exception(exc_info, True)
  File "/home/gene/.local/lib/python3.6/site-packages/jinja2/environment.py", line 780, in handle_exception
    reraise(exc_type, exc_value, tb)
  File "/home/gene/.local/lib/python3.6/site-packages/jinja2/_compat.py", line 37, in reraise
    raise value.with_traceback(tb)
  File "/home/gene/Desktop/CRM/app/templates/view_people.html", line 2, in top-level template code
    {% import 'bootstrap/wtf.html' as wtf %}
  File "/home/gene/Desktop/CRM/app/templates/base.html", line 1, in top-level template code
    {% extends 'bootstrap/base.html' %}
  File "/home/gene/.local/lib/python3.6/site-packages/flask_bootstrap/templates/bootstrap/base.html", line 1, in top-level template code
    {% block doc -%}
  File "/home/gene/.local/lib/python3.6/site-packages/flask_bootstrap/templates/bootstrap/base.html", line 4, in block "doc"
    {%- block html %}
  File "/home/gene/.local/lib/python3.6/site-packages/flask_bootstrap/templates/bootstrap/base.html", line 20, in block "html"
    {% block body -%}
  File "/home/gene/.local/lib/python3.6/site-packages/flask_bootstrap/templates/bootstrap/base.html", line 23, in block "body"
    {% block content -%}
  File "/home/gene/Desktop/CRM/app/templates/base.html", line 67, in block "content"
    {% block app_content %}{% endblock %}
  File "/home/gene/Desktop/CRM/app/templates/view_people.html", line 67, in block "app_content"
    {{ wtf.quick_form(notes_form) }}
  File "/home/gene/.local/lib/python3.6/site-packages/jinja2/runtime.py", line 579, in _invoke
    rv = self._func(*arguments)
  File "/home/gene/.local/lib/python3.6/site-packages/flask_bootstrap/templates/bootstrap/wtf.html", line 200, in template
    {{ form.hidden_tag() }}
  File "/home/gene/.local/lib/python3.6/site-packages/jinja2/environment.py", line 430, in getattr
    return getattr(obj, attribute)
jinja2.exceptions.UndefinedError: 'notes_form' is undefined
2019-01-25 15:37:19,557 INFO: ReDefined CRM Startup [in /home/gene/Desktop/CRM/app/__init__.py:53]
