2018-10-19 22:38:19,850 INFO: ReDefined CRM Startup [in /mnt/c/Users/Tyhebrewsaurus Rex/CRM/app/__init__.py:46]
2018-10-19 22:38:22,720 ERROR: Exception on /login [GET] [in /home/gene/.local/lib/python2.7/site-packages/flask/app.py:1761]
Traceback (most recent call last):
  File "/home/gene/.local/lib/python2.7/site-packages/flask/app.py", line 2292, in wsgi_app
    response = self.full_dispatch_request()
  File "/home/gene/.local/lib/python2.7/site-packages/flask/app.py", line 1815, in full_dispatch_request
    rv = self.handle_user_exception(e)
  File "/home/gene/.local/lib/python2.7/site-packages/flask/app.py", line 1718, in handle_user_exception
    reraise(exc_type, exc_value, tb)
  File "/home/gene/.local/lib/python2.7/site-packages/flask/app.py", line 1813, in full_dispatch_request
    rv = self.dispatch_request()
  File "/home/gene/.local/lib/python2.7/site-packages/flask/app.py", line 1799, in dispatch_request
    return self.view_functions[rule.endpoint](**req.view_args)
  File "/mnt/c/Users/Tyhebrewsaurus Rex/CRM/app/routes.py", line 31, in login
    return render_template('login.html', title='Sign In', form=form)
  File "/home/gene/.local/lib/python2.7/site-packages/flask/templating.py", line 135, in render_template
    context, ctx.app)
  File "/home/gene/.local/lib/python2.7/site-packages/flask/templating.py", line 117, in _render
    rv = template.render(context)
  File "/home/gene/.local/lib/python2.7/site-packages/jinja2/environment.py", line 1008, in render
    return self.environment.handle_exception(exc_info, True)
  File "/home/gene/.local/lib/python2.7/site-packages/jinja2/environment.py", line 780, in handle_exception
    reraise(exc_type, exc_value, tb)
  File "/mnt/c/Users/Tyhebrewsaurus Rex/CRM/app/templates/login.html", line 2, in top-level template code
    {% import 'bootstrap/wtf.html' as wtf %}
  File "/home/gene/.local/lib/python2.7/site-packages/flask/templating.py", line 58, in get_source
    return self._get_source_fast(environment, template)
  File "/home/gene/.local/lib/python2.7/site-packages/flask/templating.py", line 86, in _get_source_fast
    raise TemplateNotFound(template)
TemplateNotFound: bootstrap/wtf.html
2018-10-19 22:38:23,069 ERROR: Exception on /favicon.ico [GET] [in /home/gene/.local/lib/python2.7/site-packages/flask/app.py:1761]
Traceback (most recent call last):
  File "/home/gene/.local/lib/python2.7/site-packages/flask/app.py", line 2292, in wsgi_app
    response = self.full_dispatch_request()
  File "/home/gene/.local/lib/python2.7/site-packages/flask/app.py", line 1815, in full_dispatch_request
    rv = self.handle_user_exception(e)
  File "/home/gene/.local/lib/python2.7/site-packages/flask/app.py", line 1713, in handle_user_exception
    return self.handle_http_exception(e)
  File "/home/gene/.local/lib/python2.7/site-packages/flask/app.py", line 1644, in handle_http_exception
    return handler(e)
  File "/mnt/c/Users/Tyhebrewsaurus Rex/CRM/app/errors.py", line 6, in not_found_error
    return render_template('404.html'), 404
  File "/home/gene/.local/lib/python2.7/site-packages/flask/templating.py", line 135, in render_template
    context, ctx.app)
  File "/home/gene/.local/lib/python2.7/site-packages/flask/templating.py", line 117, in _render
    rv = template.render(context)
  File "/home/gene/.local/lib/python2.7/site-packages/jinja2/environment.py", line 1008, in render
    return self.environment.handle_exception(exc_info, True)
  File "/home/gene/.local/lib/python2.7/site-packages/jinja2/environment.py", line 780, in handle_exception
    reraise(exc_type, exc_value, tb)
  File "/mnt/c/Users/Tyhebrewsaurus Rex/CRM/app/templates/404.html", line 2, in top-level template code
    {% import 'bootstrap/wtf.html' as wtf %}
  File "/home/gene/.local/lib/python2.7/site-packages/flask/templating.py", line 58, in get_source
    return self._get_source_fast(environment, template)
  File "/home/gene/.local/lib/python2.7/site-packages/flask/templating.py", line 86, in _get_source_fast
    raise TemplateNotFound(template)
TemplateNotFound: bootstrap/wtf.html
2018-10-19 22:38:34,823 INFO: ReDefined CRM Startup [in /mnt/c/Users/Tyhebrewsaurus Rex/CRM/app/__init__.py:46]
2018-10-19 22:38:37,984 ERROR: Exception on /login [GET] [in /home/gene/.local/lib/python2.7/site-packages/flask/app.py:1761]
Traceback (most recent call last):
  File "/home/gene/.local/lib/python2.7/site-packages/flask/app.py", line 2292, in wsgi_app
    response = self.full_dispatch_request()
  File "/home/gene/.local/lib/python2.7/site-packages/flask/app.py", line 1815, in full_dispatch_request
    rv = self.handle_user_exception(e)
  File "/home/gene/.local/lib/python2.7/site-packages/flask/app.py", line 1718, in handle_user_exception
    reraise(exc_type, exc_value, tb)
  File "/home/gene/.local/lib/python2.7/site-packages/flask/app.py", line 1813, in full_dispatch_request
    rv = self.dispatch_request()
  File "/home/gene/.local/lib/python2.7/site-packages/flask/app.py", line 1799, in dispatch_request
    return self.view_functions[rule.endpoint](**req.view_args)
  File "/mnt/c/Users/Tyhebrewsaurus Rex/CRM/app/routes.py", line 31, in login
    return render_template('login.html', title='Sign In', form=form)
  File "/home/gene/.local/lib/python2.7/site-packages/flask/templating.py", line 135, in render_template
    context, ctx.app)
  File "/home/gene/.local/lib/python2.7/site-packages/flask/templating.py", line 117, in _render
    rv = template.render(context)
  File "/home/gene/.local/lib/python2.7/site-packages/jinja2/environment.py", line 1008, in render
    return self.environment.handle_exception(exc_info, True)
  File "/home/gene/.local/lib/python2.7/site-packages/jinja2/environment.py", line 780, in handle_exception
    reraise(exc_type, exc_value, tb)
  File "/mnt/c/Users/Tyhebrewsaurus Rex/CRM/app/templates/login.html", line 2, in top-level template code
    {% import 'bootstrap/wtf.html' as wtf %}
  File "/home/gene/.local/lib/python2.7/site-packages/flask/templating.py", line 58, in get_source
    return self._get_source_fast(environment, template)
  File "/home/gene/.local/lib/python2.7/site-packages/flask/templating.py", line 86, in _get_source_fast
    raise TemplateNotFound(template)
TemplateNotFound: bootstrap/wtf.html
2018-10-19 22:38:38,029 ERROR: Exception on /favicon.ico [GET] [in /home/gene/.local/lib/python2.7/site-packages/flask/app.py:1761]
Traceback (most recent call last):
  File "/home/gene/.local/lib/python2.7/site-packages/flask/app.py", line 2292, in wsgi_app
    response = self.full_dispatch_request()
  File "/home/gene/.local/lib/python2.7/site-packages/flask/app.py", line 1815, in full_dispatch_request
    rv = self.handle_user_exception(e)
  File "/home/gene/.local/lib/python2.7/site-packages/flask/app.py", line 1713, in handle_user_exception
    return self.handle_http_exception(e)
  File "/home/gene/.local/lib/python2.7/site-packages/flask/app.py", line 1644, in handle_http_exception
    return handler(e)
  File "/mnt/c/Users/Tyhebrewsaurus Rex/CRM/app/errors.py", line 6, in not_found_error
    return render_template('404.html'), 404
  File "/home/gene/.local/lib/python2.7/site-packages/flask/templating.py", line 135, in render_template
    context, ctx.app)
  File "/home/gene/.local/lib/python2.7/site-packages/flask/templating.py", line 117, in _render
    rv = template.render(context)
  File "/home/gene/.local/lib/python2.7/site-packages/jinja2/environment.py", line 1008, in render
    return self.environment.handle_exception(exc_info, True)
  File "/home/gene/.local/lib/python2.7/site-packages/jinja2/environment.py", line 780, in handle_exception
    reraise(exc_type, exc_value, tb)
  File "/mnt/c/Users/Tyhebrewsaurus Rex/CRM/app/templates/404.html", line 2, in top-level template code
    {% import 'bootstrap/wtf.html' as wtf %}
  File "/home/gene/.local/lib/python2.7/site-packages/flask/templating.py", line 58, in get_source
    return self._get_source_fast(environment, template)
  File "/home/gene/.local/lib/python2.7/site-packages/flask/templating.py", line 86, in _get_source_fast
    raise TemplateNotFound(template)
TemplateNotFound: bootstrap/wtf.html
2018-10-19 22:38:59,408 INFO: ReDefined CRM Startup [in /mnt/c/Users/Tyhebrewsaurus Rex/CRM/app/__init__.py:46]
2018-10-19 22:39:11,946 INFO: ReDefined CRM Startup [in /mnt/c/Users/Tyhebrewsaurus Rex/CRM/app/__init__.py:46]
