2018-11-06 19:51:24,338 ERROR: Exception on /login [POST] [in /mnt/c/Users/GM/Desktop/CRM/venv/lib/python3.6/site-packages/flask/app.py:1761]
Traceback (most recent call last):
  File "/mnt/c/Users/GM/Desktop/CRM/venv/lib/python3.6/site-packages/flask/app.py", line 2292, in wsgi_app
    response = self.full_dispatch_request()
  File "/mnt/c/Users/GM/Desktop/CRM/venv/lib/python3.6/site-packages/flask/app.py", line 1815, in full_dispatch_request
    rv = self.handle_user_exception(e)
  File "/mnt/c/Users/GM/Desktop/CRM/venv/lib/python3.6/site-packages/flask/app.py", line 1718, in handle_user_exception
    reraise(exc_type, exc_value, tb)
  File "/mnt/c/Users/GM/Desktop/CRM/venv/lib/python3.6/site-packages/flask/_compat.py", line 35, in reraise
    raise value
  File "/mnt/c/Users/GM/Desktop/CRM/venv/lib/python3.6/site-packages/flask/app.py", line 1813, in full_dispatch_request
    rv = self.dispatch_request()
  File "/mnt/c/Users/GM/Desktop/CRM/venv/lib/python3.6/site-packages/flask/app.py", line 1799, in dispatch_request
    return self.view_functions[rule.endpoint](**req.view_args)
  File "/mnt/c/Users/GM/Desktop/CRM/app/routes.py", line 85, in login
    account=User.query.filter_by(username=form.username.data).first()
  File "/mnt/c/Users/GM/Desktop/CRM/venv/lib/python3.6/site-packages/flask_sqlalchemy/__init__.py", line 512, in __get__
    mapper = orm.class_mapper(type)
  File "/mnt/c/Users/GM/Desktop/CRM/venv/lib/python3.6/site-packages/sqlalchemy/orm/base.py", line 421, in class_mapper
    mapper = _inspect_mapped_class(class_, configure=configure)
  File "/mnt/c/Users/GM/Desktop/CRM/venv/lib/python3.6/site-packages/sqlalchemy/orm/base.py", line 400, in _inspect_mapped_class
    mapper._configure_all()
  File "/mnt/c/Users/GM/Desktop/CRM/venv/lib/python3.6/site-packages/sqlalchemy/orm/mapper.py", line 1276, in _configure_all
    configure_mappers()
  File "/mnt/c/Users/GM/Desktop/CRM/venv/lib/python3.6/site-packages/sqlalchemy/orm/mapper.py", line 3033, in configure_mappers
    mapper._post_configure_properties()
  File "/mnt/c/Users/GM/Desktop/CRM/venv/lib/python3.6/site-packages/sqlalchemy/orm/mapper.py", line 1832, in _post_configure_properties
    prop.init()
  File "/mnt/c/Users/GM/Desktop/CRM/venv/lib/python3.6/site-packages/sqlalchemy/orm/interfaces.py", line 183, in init
    self.do_init()
  File "/mnt/c/Users/GM/Desktop/CRM/venv/lib/python3.6/site-packages/sqlalchemy/orm/relationships.py", line 1659, in do_init
    self._generate_backref()
  File "/mnt/c/Users/GM/Desktop/CRM/venv/lib/python3.6/site-packages/sqlalchemy/orm/relationships.py", line 1849, in _generate_backref
    (backref_key, self, m))
sqlalchemy.exc.ArgumentError: Error creating backref 'profilenotes' on relationship 'People.ProfileNotes': property of that name exists on mapper 'Mapper|ProfileNotes|profile_notes'
2018-11-06 19:51:49,072 INFO: ReDefined CRM Startup [in /mnt/c/Users/GM/Desktop/CRM/app/__init__.py:53]
2018-11-06 19:53:32,262 INFO: ReDefined CRM Startup [in /mnt/c/Users/GM/Desktop/CRM/app/__init__.py:53]
2018-11-06 19:53:34,839 INFO: ReDefined CRM Startup [in /mnt/c/Users/GM/Desktop/CRM/app/__init__.py:53]
2018-11-06 19:53:40,134 ERROR: Exception on /login [POST] [in /mnt/c/Users/GM/Desktop/CRM/venv/lib/python3.6/site-packages/flask/app.py:1761]
Traceback (most recent call last):
  File "/mnt/c/Users/GM/Desktop/CRM/venv/lib/python3.6/site-packages/flask/app.py", line 2292, in wsgi_app
    response = self.full_dispatch_request()
  File "/mnt/c/Users/GM/Desktop/CRM/venv/lib/python3.6/site-packages/flask/app.py", line 1815, in full_dispatch_request
    rv = self.handle_user_exception(e)
  File "/mnt/c/Users/GM/Desktop/CRM/venv/lib/python3.6/site-packages/flask/app.py", line 1718, in handle_user_exception
    reraise(exc_type, exc_value, tb)
  File "/mnt/c/Users/GM/Desktop/CRM/venv/lib/python3.6/site-packages/flask/_compat.py", line 35, in reraise
    raise value
  File "/mnt/c/Users/GM/Desktop/CRM/venv/lib/python3.6/site-packages/flask/app.py", line 1813, in full_dispatch_request
    rv = self.dispatch_request()
  File "/mnt/c/Users/GM/Desktop/CRM/venv/lib/python3.6/site-packages/flask/app.py", line 1799, in dispatch_request
    return self.view_functions[rule.endpoint](**req.view_args)
  File "/mnt/c/Users/GM/Desktop/CRM/app/routes.py", line 85, in login
    account=User.query.filter_by(username=form.username.data).first()
  File "/mnt/c/Users/GM/Desktop/CRM/venv/lib/python3.6/site-packages/flask_sqlalchemy/__init__.py", line 512, in __get__
    mapper = orm.class_mapper(type)
  File "/mnt/c/Users/GM/Desktop/CRM/venv/lib/python3.6/site-packages/sqlalchemy/orm/base.py", line 421, in class_mapper
    mapper = _inspect_mapped_class(class_, configure=configure)
  File "/mnt/c/Users/GM/Desktop/CRM/venv/lib/python3.6/site-packages/sqlalchemy/orm/base.py", line 400, in _inspect_mapped_class
    mapper._configure_all()
  File "/mnt/c/Users/GM/Desktop/CRM/venv/lib/python3.6/site-packages/sqlalchemy/orm/mapper.py", line 1276, in _configure_all
    configure_mappers()
  File "/mnt/c/Users/GM/Desktop/CRM/venv/lib/python3.6/site-packages/sqlalchemy/orm/mapper.py", line 3033, in configure_mappers
    mapper._post_configure_properties()
  File "/mnt/c/Users/GM/Desktop/CRM/venv/lib/python3.6/site-packages/sqlalchemy/orm/mapper.py", line 1832, in _post_configure_properties
    prop.init()
  File "/mnt/c/Users/GM/Desktop/CRM/venv/lib/python3.6/site-packages/sqlalchemy/orm/interfaces.py", line 183, in init
    self.do_init()
  File "/mnt/c/Users/GM/Desktop/CRM/venv/lib/python3.6/site-packages/sqlalchemy/orm/relationships.py", line 1659, in do_init
    self._generate_backref()
  File "/mnt/c/Users/GM/Desktop/CRM/venv/lib/python3.6/site-packages/sqlalchemy/orm/relationships.py", line 1849, in _generate_backref
    (backref_key, self, m))
sqlalchemy.exc.ArgumentError: Error creating backref 'profilenotes' on relationship 'People.ProfileNotes': property of that name exists on mapper 'Mapper|ProfileNotes|profile_notes'
2018-11-06 19:55:23,869 INFO: ReDefined CRM Startup [in /mnt/c/Users/GM/Desktop/CRM/app/__init__.py:53]
2018-11-06 19:55:26,657 INFO: ReDefined CRM Startup [in /mnt/c/Users/GM/Desktop/CRM/app/__init__.py:53]
2018-11-06 19:55:30,202 INFO: ReDefined CRM Startup [in /mnt/c/Users/GM/Desktop/CRM/app/__init__.py:53]
2018-11-06 19:56:12,396 INFO: ReDefined CRM Startup [in /mnt/c/Users/GM/Desktop/CRM/app/__init__.py:53]
2018-11-06 20:03:20,028 INFO: ReDefined CRM Startup [in /mnt/c/Users/GM/Desktop/CRM/app/__init__.py:53]
2018-11-06 20:03:49,601 INFO: ReDefined CRM Startup [in /mnt/c/Users/GM/Desktop/CRM/app/__init__.py:53]
2018-11-06 20:06:55,809 INFO: ReDefined CRM Startup [in /mnt/c/Users/GM/Desktop/CRM/app/__init__.py:53]
2018-11-06 20:36:29,845 INFO: ReDefined CRM Startup [in /mnt/c/Users/GM/Desktop/CRM/app/__init__.py:53]
2018-11-06 20:36:41,056 ERROR: Exception on /view_people/1 [POST] [in /mnt/c/Users/GM/Desktop/CRM/venv/lib/python3.6/site-packages/flask/app.py:1761]
Traceback (most recent call last):
  File "/mnt/c/Users/GM/Desktop/CRM/venv/lib/python3.6/site-packages/flask/app.py", line 2292, in wsgi_app
    response = self.full_dispatch_request()
  File "/mnt/c/Users/GM/Desktop/CRM/venv/lib/python3.6/site-packages/flask/app.py", line 1815, in full_dispatch_request
    rv = self.handle_user_exception(e)
  File "/mnt/c/Users/GM/Desktop/CRM/venv/lib/python3.6/site-packages/flask/app.py", line 1718, in handle_user_exception
    reraise(exc_type, exc_value, tb)
  File "/mnt/c/Users/GM/Desktop/CRM/venv/lib/python3.6/site-packages/flask/_compat.py", line 35, in reraise
    raise value
  File "/mnt/c/Users/GM/Desktop/CRM/venv/lib/python3.6/site-packages/flask/app.py", line 1813, in full_dispatch_request
    rv = self.dispatch_request()
  File "/mnt/c/Users/GM/Desktop/CRM/venv/lib/python3.6/site-packages/flask/app.py", line 1799, in dispatch_request
    return self.view_functions[rule.endpoint](**req.view_args)
  File "/mnt/c/Users/GM/Desktop/CRM/venv/lib/python3.6/site-packages/flask_login/utils.py", line 261, in decorated_view
    return func(*args, **kwargs)
  File "/mnt/c/Users/GM/Desktop/CRM/app/routes.py", line 79, in view_people
    return redirect(url_for('/view_people/<people_id>'))
  File "/mnt/c/Users/GM/Desktop/CRM/venv/lib/python3.6/site-packages/flask/helpers.py", line 356, in url_for
    return appctx.app.handle_url_build_error(error, endpoint, values)
  File "/mnt/c/Users/GM/Desktop/CRM/venv/lib/python3.6/site-packages/flask/app.py", line 2061, in handle_url_build_error
    reraise(exc_type, exc_value, tb)
  File "/mnt/c/Users/GM/Desktop/CRM/venv/lib/python3.6/site-packages/flask/_compat.py", line 35, in reraise
    raise value
  File "/mnt/c/Users/GM/Desktop/CRM/venv/lib/python3.6/site-packages/flask/helpers.py", line 345, in url_for
    force_external=external)
  File "/mnt/c/Users/GM/Desktop/CRM/venv/lib/python3.6/site-packages/werkzeug/routing.py", line 1776, in build
    raise BuildError(endpoint, values, method, self)
werkzeug.routing.BuildError: Could not build url for endpoint '/view_people/<people_id>'. Did you mean 'view_people' instead?
2018-11-06 20:37:34,040 INFO: ReDefined CRM Startup [in /mnt/c/Users/GM/Desktop/CRM/app/__init__.py:53]
