2019-01-24 20:18:19,478 ERROR: Exception on /recentsales [GET] [in /home/gene/.local/lib/python3.6/site-packages/flask/app.py:1761]
Traceback (most recent call last):
  File "/home/gene/.local/lib/python3.6/site-packages/flask/app.py", line 2292, in wsgi_app
    response = self.full_dispatch_request()
  File "/home/gene/.local/lib/python3.6/site-packages/flask/app.py", line 1815, in full_dispatch_request
    rv = self.handle_user_exception(e)
  File "/home/gene/.local/lib/python3.6/site-packages/flask/app.py", line 1718, in handle_user_exception
    reraise(exc_type, exc_value, tb)
  File "/home/gene/.local/lib/python3.6/site-packages/flask/_compat.py", line 35, in reraise
    raise value
  File "/home/gene/.local/lib/python3.6/site-packages/flask/app.py", line 1813, in full_dispatch_request
    rv = self.dispatch_request()
  File "/home/gene/.local/lib/python3.6/site-packages/flask/app.py", line 1799, in dispatch_request
    return self.view_functions[rule.endpoint](**req.view_args)
  File "/home/gene/.local/lib/python3.6/site-packages/flask_login/utils.py", line 261, in decorated_view
    return func(*args, **kwargs)
  File "/home/gene/Desktop/CRM/app/routes.py", line 127, in recentsales
    tot_sales = total_sales(current_user)
  File "/home/gene/Desktop/CRM/app/queryfunc.py", line 18, in total_sales
    for sales in alldeals.price:
AttributeError: 'list' object has no attribute 'price'
2019-01-24 20:18:59,493 INFO: ReDefined CRM Startup [in /home/gene/Desktop/CRM/app/__init__.py:53]
2019-01-24 20:19:02,498 ERROR: Exception on /recentsales [GET] [in /home/gene/.local/lib/python3.6/site-packages/flask/app.py:1761]
Traceback (most recent call last):
  File "/home/gene/.local/lib/python3.6/site-packages/flask/app.py", line 2292, in wsgi_app
    response = self.full_dispatch_request()
  File "/home/gene/.local/lib/python3.6/site-packages/flask/app.py", line 1815, in full_dispatch_request
    rv = self.handle_user_exception(e)
  File "/home/gene/.local/lib/python3.6/site-packages/flask/app.py", line 1718, in handle_user_exception
    reraise(exc_type, exc_value, tb)
  File "/home/gene/.local/lib/python3.6/site-packages/flask/_compat.py", line 35, in reraise
    raise value
  File "/home/gene/.local/lib/python3.6/site-packages/flask/app.py", line 1813, in full_dispatch_request
    rv = self.dispatch_request()
  File "/home/gene/.local/lib/python3.6/site-packages/flask/app.py", line 1799, in dispatch_request
    return self.view_functions[rule.endpoint](**req.view_args)
  File "/home/gene/.local/lib/python3.6/site-packages/flask_login/utils.py", line 261, in decorated_view
    return func(*args, **kwargs)
  File "/home/gene/Desktop/CRM/app/routes.py", line 127, in recentsales
    tot_sales = total_sales(current_user)
  File "/home/gene/Desktop/CRM/app/queryfunc.py", line 18, in total_sales
    for sales in alldeals[9]:
IndexError: list index out of range
2019-01-24 20:19:15,039 INFO: ReDefined CRM Startup [in /home/gene/Desktop/CRM/app/__init__.py:53]
2019-01-24 20:19:16,089 ERROR: Exception on /recentsales [GET] [in /home/gene/.local/lib/python3.6/site-packages/flask/app.py:1761]
Traceback (most recent call last):
  File "/home/gene/.local/lib/python3.6/site-packages/flask/app.py", line 2292, in wsgi_app
    response = self.full_dispatch_request()
  File "/home/gene/.local/lib/python3.6/site-packages/flask/app.py", line 1815, in full_dispatch_request
    rv = self.handle_user_exception(e)
  File "/home/gene/.local/lib/python3.6/site-packages/flask/app.py", line 1718, in handle_user_exception
    reraise(exc_type, exc_value, tb)
  File "/home/gene/.local/lib/python3.6/site-packages/flask/_compat.py", line 35, in reraise
    raise value
  File "/home/gene/.local/lib/python3.6/site-packages/flask/app.py", line 1813, in full_dispatch_request
    rv = self.dispatch_request()
  File "/home/gene/.local/lib/python3.6/site-packages/flask/app.py", line 1799, in dispatch_request
    return self.view_functions[rule.endpoint](**req.view_args)
  File "/home/gene/.local/lib/python3.6/site-packages/flask_login/utils.py", line 261, in decorated_view
    return func(*args, **kwargs)
  File "/home/gene/Desktop/CRM/app/routes.py", line 127, in recentsales
    tot_sales = total_sales(current_user)
  File "/home/gene/Desktop/CRM/app/queryfunc.py", line 18, in total_sales
    for sales in alldeals[price]:
NameError: name 'price' is not defined
2019-01-24 20:19:25,805 INFO: ReDefined CRM Startup [in /home/gene/Desktop/CRM/app/__init__.py:53]
2019-01-24 20:19:27,515 ERROR: Exception on /recentsales [GET] [in /home/gene/.local/lib/python3.6/site-packages/flask/app.py:1761]
Traceback (most recent call last):
  File "/home/gene/.local/lib/python3.6/site-packages/flask/app.py", line 2292, in wsgi_app
    response = self.full_dispatch_request()
  File "/home/gene/.local/lib/python3.6/site-packages/flask/app.py", line 1815, in full_dispatch_request
    rv = self.handle_user_exception(e)
  File "/home/gene/.local/lib/python3.6/site-packages/flask/app.py", line 1718, in handle_user_exception
    reraise(exc_type, exc_value, tb)
  File "/home/gene/.local/lib/python3.6/site-packages/flask/_compat.py", line 35, in reraise
    raise value
  File "/home/gene/.local/lib/python3.6/site-packages/flask/app.py", line 1813, in full_dispatch_request
    rv = self.dispatch_request()
  File "/home/gene/.local/lib/python3.6/site-packages/flask/app.py", line 1799, in dispatch_request
    return self.view_functions[rule.endpoint](**req.view_args)
  File "/home/gene/.local/lib/python3.6/site-packages/flask_login/utils.py", line 261, in decorated_view
    return func(*args, **kwargs)
  File "/home/gene/Desktop/CRM/app/routes.py", line 127, in recentsales
    tot_sales = total_sales(current_user)
  File "/home/gene/Desktop/CRM/app/queryfunc.py", line 18, in total_sales
    for sales in alldeals["price"]:
TypeError: list indices must be integers or slices, not str
2019-01-24 20:20:25,597 INFO: ReDefined CRM Startup [in /home/gene/Desktop/CRM/app/__init__.py:53]
2019-01-24 20:22:00,302 INFO: ReDefined CRM Startup [in /home/gene/Desktop/CRM/app/__init__.py:53]
2019-01-24 20:22:01,761 ERROR: Exception on /recentsales [GET] [in /home/gene/.local/lib/python3.6/site-packages/flask/app.py:1761]
Traceback (most recent call last):
  File "/home/gene/.local/lib/python3.6/site-packages/flask/app.py", line 2292, in wsgi_app
    response = self.full_dispatch_request()
  File "/home/gene/.local/lib/python3.6/site-packages/flask/app.py", line 1815, in full_dispatch_request
    rv = self.handle_user_exception(e)
  File "/home/gene/.local/lib/python3.6/site-packages/flask/app.py", line 1718, in handle_user_exception
    reraise(exc_type, exc_value, tb)
  File "/home/gene/.local/lib/python3.6/site-packages/flask/_compat.py", line 35, in reraise
    raise value
  File "/home/gene/.local/lib/python3.6/site-packages/flask/app.py", line 1813, in full_dispatch_request
    rv = self.dispatch_request()
  File "/home/gene/.local/lib/python3.6/site-packages/flask/app.py", line 1799, in dispatch_request
    return self.view_functions[rule.endpoint](**req.view_args)
  File "/home/gene/.local/lib/python3.6/site-packages/flask_login/utils.py", line 261, in decorated_view
    return func(*args, **kwargs)
  File "/home/gene/Desktop/CRM/app/routes.py", line 127, in recentsales
    tot_sales = total_sales(current_user)
  File "/home/gene/Desktop/CRM/app/queryfunc.py", line 20, in total_sales
    for sales in alldeals[9]:
IndexError: list index out of range
2019-01-24 20:22:14,167 INFO: ReDefined CRM Startup [in /home/gene/Desktop/CRM/app/__init__.py:53]
2019-01-24 20:23:32,502 INFO: ReDefined CRM Startup [in /home/gene/Desktop/CRM/app/__init__.py:53]
2019-01-24 20:34:22,938 INFO: ReDefined CRM Startup [in /home/gene/Desktop/CRM/app/__init__.py:53]
2019-01-24 20:34:26,420 ERROR: Exception on /recentsales [GET] [in /home/gene/.local/lib/python3.6/site-packages/flask/app.py:1761]
Traceback (most recent call last):
  File "/home/gene/.local/lib/python3.6/site-packages/flask/app.py", line 2292, in wsgi_app
    response = self.full_dispatch_request()
  File "/home/gene/.local/lib/python3.6/site-packages/flask/app.py", line 1815, in full_dispatch_request
    rv = self.handle_user_exception(e)
  File "/home/gene/.local/lib/python3.6/site-packages/flask/app.py", line 1718, in handle_user_exception
    reraise(exc_type, exc_value, tb)
  File "/home/gene/.local/lib/python3.6/site-packages/flask/_compat.py", line 35, in reraise
    raise value
  File "/home/gene/.local/lib/python3.6/site-packages/flask/app.py", line 1813, in full_dispatch_request
    rv = self.dispatch_request()
  File "/home/gene/.local/lib/python3.6/site-packages/flask/app.py", line 1799, in dispatch_request
    return self.view_functions[rule.endpoint](**req.view_args)
  File "/home/gene/.local/lib/python3.6/site-packages/flask_login/utils.py", line 261, in decorated_view
    return func(*args, **kwargs)
  File "/home/gene/Desktop/CRM/app/routes.py", line 128, in recentsales
    for sales_nums in all_closed_deals.price:
AttributeError: 'list' object has no attribute 'price'
2019-01-24 20:36:55,311 INFO: ReDefined CRM Startup [in /home/gene/Desktop/CRM/app/__init__.py:53]
