2018-11-01 19:51:41,649 ERROR: Exception on /people [GET] [in /mnt/c/Users/GM/Desktop/CRM/venv/lib/python3.6/site-packages/flask/app.py:1761]
Traceback (most recent call last):
  File "/mnt/c/Users/GM/Desktop/CRM/venv/lib/python3.6/site-packages/flask/app.py", line 2292, in wsgi_app
    response = self.full_dispatch_request()
  File "/mnt/c/Users/GM/Desktop/CRM/venv/lib/python3.6/site-packages/flask/app.py", line 1815, in full_dispatch_request
    rv = self.handle_user_exception(e)
  File "/mnt/c/Users/GM/Desktop/CRM/venv/lib/python3.6/site-packages/flask/app.py", line 1718, in handle_user_exception
    reraise(exc_type, exc_value, tb)
  File "/mnt/c/Users/GM/Desktop/CRM/venv/lib/python3.6/site-packages/flask/_compat.py", line 35, in reraise
    raise value
  File "/mnt/c/Users/GM/Desktop/CRM/venv/lib/python3.6/site-packages/flask/app.py", line 1813, in full_dispatch_request
    rv = self.dispatch_request()
  File "/mnt/c/Users/GM/Desktop/CRM/venv/lib/python3.6/site-packages/flask/app.py", line 1799, in dispatch_request
    return self.view_functions[rule.endpoint](**req.view_args)
  File "/mnt/c/Users/GM/Desktop/CRM/venv/lib/python3.6/site-packages/flask_login/utils.py", line 261, in decorated_view
    return func(*args, **kwargs)
  File "/mnt/c/Users/GM/Desktop/CRM/app/routes.py", line 47, in people
    return render_template('people.html', title='People', all_people=all_people)
  File "/mnt/c/Users/GM/Desktop/CRM/venv/lib/python3.6/site-packages/flask/templating.py", line 135, in render_template
    context, ctx.app)
  File "/mnt/c/Users/GM/Desktop/CRM/venv/lib/python3.6/site-packages/flask/templating.py", line 117, in _render
    rv = template.render(context)
  File "/mnt/c/Users/GM/Desktop/CRM/venv/lib/python3.6/site-packages/jinja2/asyncsupport.py", line 76, in render
    return original_render(self, *args, **kwargs)
  File "/mnt/c/Users/GM/Desktop/CRM/venv/lib/python3.6/site-packages/jinja2/environment.py", line 1008, in render
    return self.environment.handle_exception(exc_info, True)
  File "/mnt/c/Users/GM/Desktop/CRM/venv/lib/python3.6/site-packages/jinja2/environment.py", line 780, in handle_exception
    reraise(exc_type, exc_value, tb)
  File "/mnt/c/Users/GM/Desktop/CRM/venv/lib/python3.6/site-packages/jinja2/_compat.py", line 37, in reraise
    raise value.with_traceback(tb)
  File "/mnt/c/Users/GM/Desktop/CRM/app/templates/people.html", line 2, in top-level template code
    {% import 'bootstrap/wtf.html' as wtf %}
  File "/mnt/c/Users/GM/Desktop/CRM/app/templates/base.html", line 1, in top-level template code
    {% extends 'bootstrap/base.html' %}
  File "/mnt/c/Users/GM/Desktop/CRM/venv/lib/python3.6/site-packages/flask_bootstrap/templates/bootstrap/base.html", line 1, in top-level template code
    {% block doc -%}
  File "/mnt/c/Users/GM/Desktop/CRM/venv/lib/python3.6/site-packages/flask_bootstrap/templates/bootstrap/base.html", line 4, in block "doc"
    {%- block html %}
  File "/mnt/c/Users/GM/Desktop/CRM/venv/lib/python3.6/site-packages/flask_bootstrap/templates/bootstrap/base.html", line 20, in block "html"
    {% block body -%}
  File "/mnt/c/Users/GM/Desktop/CRM/venv/lib/python3.6/site-packages/flask_bootstrap/templates/bootstrap/base.html", line 23, in block "body"
    {% block content -%}
  File "/mnt/c/Users/GM/Desktop/CRM/app/templates/base.html", line 51, in block "content"
    {% block app_content %}{% endblock %}
  File "/mnt/c/Users/GM/Desktop/CRM/app/templates/people.html", line 8, in block "app_content"
    <button type="button" class="btn btn-success"><a href="{{ url_for('add_client') }}">Add Client</a></button>
  File "/mnt/c/Users/GM/Desktop/CRM/venv/lib/python3.6/site-packages/flask/helpers.py", line 356, in url_for
    return appctx.app.handle_url_build_error(error, endpoint, values)
  File "/mnt/c/Users/GM/Desktop/CRM/venv/lib/python3.6/site-packages/flask/app.py", line 2061, in handle_url_build_error
    reraise(exc_type, exc_value, tb)
  File "/mnt/c/Users/GM/Desktop/CRM/venv/lib/python3.6/site-packages/flask/_compat.py", line 35, in reraise
    raise value
  File "/mnt/c/Users/GM/Desktop/CRM/venv/lib/python3.6/site-packages/flask/helpers.py", line 345, in url_for
    force_external=external)
  File "/mnt/c/Users/GM/Desktop/CRM/venv/lib/python3.6/site-packages/werkzeug/routing.py", line 1776, in build
    raise BuildError(endpoint, values, method, self)
werkzeug.routing.BuildError: Could not build url for endpoint 'add_client'. Did you mean 'search_clientt' instead?
2018-11-01 19:52:18,448 INFO: ReDefined CRM Startup [in /mnt/c/Users/GM/Desktop/CRM/app/__init__.py:53]
2018-11-01 20:19:34,136 INFO: ReDefined CRM Startup [in /mnt/c/Users/GM/Desktop/CRM/app/__init__.py:53]
2018-11-01 20:24:04,639 INFO: ReDefined CRM Startup [in /mnt/c/Users/GM/Desktop/CRM/app/__init__.py:53]
2018-11-01 20:37:04,592 INFO: ReDefined CRM Startup [in /mnt/c/Users/GM/Desktop/CRM/app/__init__.py:53]
2018-11-01 20:38:20,335 INFO: ReDefined CRM Startup [in /mnt/c/Users/GM/Desktop/CRM/app/__init__.py:53]
2018-11-01 20:39:11,322 INFO: ReDefined CRM Startup [in /mnt/c/Users/GM/Desktop/CRM/app/__init__.py:53]
2018-11-01 20:44:48,420 INFO: ReDefined CRM Startup [in /mnt/c/Users/GM/Desktop/CRM/app/__init__.py:53]
2018-11-01 20:46:14,884 INFO: ReDefined CRM Startup [in /mnt/c/Users/GM/Desktop/CRM/app/__init__.py:53]
2018-11-01 20:46:16,991 INFO: ReDefined CRM Startup [in /mnt/c/Users/GM/Desktop/CRM/app/__init__.py:53]
2018-11-01 20:47:11,099 INFO: ReDefined CRM Startup [in /mnt/c/Users/GM/Desktop/CRM/app/__init__.py:53]
2018-11-03 01:02:21,836 INFO: ReDefined CRM Startup [in /mnt/c/Users/Tyhebrewsaurus Rex/CRM/app/__init__.py:53]
2018-11-03 01:02:28,132 INFO: ReDefined CRM Startup [in /mnt/c/Users/Tyhebrewsaurus Rex/CRM/app/__init__.py:53]
2018-11-06 19:08:24,543 INFO: ReDefined CRM Startup [in /mnt/c/Users/GM/Desktop/CRM/app/__init__.py:53]
2018-11-06 19:08:33,270 INFO: ReDefined CRM Startup [in /mnt/c/Users/GM/Desktop/CRM/app/__init__.py:53]
2018-11-06 19:09:28,700 INFO: ReDefined CRM Startup [in /mnt/c/Users/GM/Desktop/CRM/app/__init__.py:53]
2018-11-06 19:09:32,638 INFO: ReDefined CRM Startup [in /mnt/c/Users/GM/Desktop/CRM/app/__init__.py:53]
2018-11-06 19:09:41,416 INFO: ReDefined CRM Startup [in /mnt/c/Users/GM/Desktop/CRM/app/__init__.py:53]
2018-11-06 19:49:28,130 INFO: ReDefined CRM Startup [in /mnt/c/Users/GM/Desktop/CRM/app/__init__.py:53]
2018-11-06 19:49:36,675 ERROR: Exception on /login [POST] [in /mnt/c/Users/GM/Desktop/CRM/venv/lib/python3.6/site-packages/flask/app.py:1761]
Traceback (most recent call last):
  File "/mnt/c/Users/GM/Desktop/CRM/venv/lib/python3.6/site-packages/flask/app.py", line 2292, in wsgi_app
    response = self.full_dispatch_request()
  File "/mnt/c/Users/GM/Desktop/CRM/venv/lib/python3.6/site-packages/flask/app.py", line 1815, in full_dispatch_request
    rv = self.handle_user_exception(e)
  File "/mnt/c/Users/GM/Desktop/CRM/venv/lib/python3.6/site-packages/flask/app.py", line 1718, in handle_user_exception
    reraise(exc_type, exc_value, tb)
  File "/mnt/c/Users/GM/Desktop/CRM/venv/lib/python3.6/site-packages/flask/_compat.py", line 35, in reraise
    raise value
  File "/mnt/c/Users/GM/Desktop/CRM/venv/lib/python3.6/site-packages/flask/app.py", line 1813, in full_dispatch_request
    rv = self.dispatch_request()
  File "/mnt/c/Users/GM/Desktop/CRM/venv/lib/python3.6/site-packages/flask/app.py", line 1799, in dispatch_request
    return self.view_functions[rule.endpoint](**req.view_args)
  File "/mnt/c/Users/GM/Desktop/CRM/app/routes.py", line 85, in login
    account=User.query.filter_by(username=form.username.data).first()
  File "/mnt/c/Users/GM/Desktop/CRM/venv/lib/python3.6/site-packages/flask_sqlalchemy/__init__.py", line 512, in __get__
    mapper = orm.class_mapper(type)
  File "/mnt/c/Users/GM/Desktop/CRM/venv/lib/python3.6/site-packages/sqlalchemy/orm/base.py", line 421, in class_mapper
    mapper = _inspect_mapped_class(class_, configure=configure)
  File "/mnt/c/Users/GM/Desktop/CRM/venv/lib/python3.6/site-packages/sqlalchemy/orm/base.py", line 400, in _inspect_mapped_class
    mapper._configure_all()
  File "/mnt/c/Users/GM/Desktop/CRM/venv/lib/python3.6/site-packages/sqlalchemy/orm/mapper.py", line 1276, in _configure_all
    configure_mappers()
  File "/mnt/c/Users/GM/Desktop/CRM/venv/lib/python3.6/site-packages/sqlalchemy/orm/mapper.py", line 3033, in configure_mappers
    mapper._post_configure_properties()
  File "/mnt/c/Users/GM/Desktop/CRM/venv/lib/python3.6/site-packages/sqlalchemy/orm/mapper.py", line 1832, in _post_configure_properties
    prop.init()
  File "/mnt/c/Users/GM/Desktop/CRM/venv/lib/python3.6/site-packages/sqlalchemy/orm/interfaces.py", line 183, in init
    self.do_init()
  File "/mnt/c/Users/GM/Desktop/CRM/venv/lib/python3.6/site-packages/sqlalchemy/orm/relationships.py", line 1659, in do_init
    self._generate_backref()
  File "/mnt/c/Users/GM/Desktop/CRM/venv/lib/python3.6/site-packages/sqlalchemy/orm/relationships.py", line 1849, in _generate_backref
    (backref_key, self, m))
sqlalchemy.exc.ArgumentError: Error creating backref 'profilenotes' on relationship 'People.ProfileNotes': property of that name exists on mapper 'Mapper|ProfileNotes|profile_notes'
2018-11-06 19:50:11,416 INFO: ReDefined CRM Startup [in /mnt/c/Users/GM/Desktop/CRM/app/__init__.py:53]
2018-11-06 19:50:15,118 INFO: ReDefined CRM Startup [in /mnt/c/Users/GM/Desktop/CRM/app/__init__.py:53]
2018-11-06 19:51:18,784 INFO: ReDefined CRM Startup [in /mnt/c/Users/GM/Desktop/CRM/app/__init__.py:53]
