2019-01-24 20:36:58,221 ERROR: Exception on /recentsales [GET] [in /home/gene/.local/lib/python3.6/site-packages/flask/app.py:1761]
Traceback (most recent call last):
  File "/home/gene/.local/lib/python3.6/site-packages/flask/app.py", line 2292, in wsgi_app
    response = self.full_dispatch_request()
  File "/home/gene/.local/lib/python3.6/site-packages/flask/app.py", line 1815, in full_dispatch_request
    rv = self.handle_user_exception(e)
  File "/home/gene/.local/lib/python3.6/site-packages/flask/app.py", line 1718, in handle_user_exception
    reraise(exc_type, exc_value, tb)
  File "/home/gene/.local/lib/python3.6/site-packages/flask/_compat.py", line 35, in reraise
    raise value
  File "/home/gene/.local/lib/python3.6/site-packages/flask/app.py", line 1813, in full_dispatch_request
    rv = self.dispatch_request()
  File "/home/gene/.local/lib/python3.6/site-packages/flask/app.py", line 1799, in dispatch_request
    return self.view_functions[rule.endpoint](**req.view_args)
  File "/home/gene/.local/lib/python3.6/site-packages/flask_login/utils.py", line 261, in decorated_view
    return func(*args, **kwargs)
  File "/home/gene/Desktop/CRM/app/routes.py", line 129, in recentsales
    for price in prices:
TypeError: 'ClosedDeals' object is not iterable
2019-01-24 20:39:39,901 INFO: ReDefined CRM Startup [in /home/gene/Desktop/CRM/app/__init__.py:53]
2019-01-24 20:39:42,280 ERROR: Exception on /recentsales [GET] [in /home/gene/.local/lib/python3.6/site-packages/flask/app.py:1761]
Traceback (most recent call last):
  File "/home/gene/.local/lib/python3.6/site-packages/flask/app.py", line 2292, in wsgi_app
    response = self.full_dispatch_request()
  File "/home/gene/.local/lib/python3.6/site-packages/flask/app.py", line 1815, in full_dispatch_request
    rv = self.handle_user_exception(e)
  File "/home/gene/.local/lib/python3.6/site-packages/flask/app.py", line 1718, in handle_user_exception
    reraise(exc_type, exc_value, tb)
  File "/home/gene/.local/lib/python3.6/site-packages/flask/_compat.py", line 35, in reraise
    raise value
  File "/home/gene/.local/lib/python3.6/site-packages/flask/app.py", line 1813, in full_dispatch_request
    rv = self.dispatch_request()
  File "/home/gene/.local/lib/python3.6/site-packages/flask/app.py", line 1799, in dispatch_request
    return self.view_functions[rule.endpoint](**req.view_args)
  File "/home/gene/.local/lib/python3.6/site-packages/flask_login/utils.py", line 261, in decorated_view
    return func(*args, **kwargs)
  File "/home/gene/Desktop/CRM/app/routes.py", line 127, in recentsales
    tot_sales = view_closed_deal_prices(current_user)
  File "/home/gene/Desktop/CRM/app/queryfunc.py", line 47, in view_closed_deal_prices
    for prices in all_closed.price:
AttributeError: 'list' object has no attribute 'price'
2019-01-24 20:40:23,960 INFO: ReDefined CRM Startup [in /home/gene/Desktop/CRM/app/__init__.py:53]
2019-01-24 20:40:26,162 ERROR: Exception on /recentsales [GET] [in /home/gene/.local/lib/python3.6/site-packages/flask/app.py:1761]
Traceback (most recent call last):
  File "/home/gene/.local/lib/python3.6/site-packages/flask/app.py", line 2292, in wsgi_app
    response = self.full_dispatch_request()
  File "/home/gene/.local/lib/python3.6/site-packages/flask/app.py", line 1815, in full_dispatch_request
    rv = self.handle_user_exception(e)
  File "/home/gene/.local/lib/python3.6/site-packages/flask/app.py", line 1718, in handle_user_exception
    reraise(exc_type, exc_value, tb)
  File "/home/gene/.local/lib/python3.6/site-packages/flask/_compat.py", line 35, in reraise
    raise value
  File "/home/gene/.local/lib/python3.6/site-packages/flask/app.py", line 1813, in full_dispatch_request
    rv = self.dispatch_request()
  File "/home/gene/.local/lib/python3.6/site-packages/flask/app.py", line 1799, in dispatch_request
    return self.view_functions[rule.endpoint](**req.view_args)
  File "/home/gene/.local/lib/python3.6/site-packages/flask_login/utils.py", line 261, in decorated_view
    return func(*args, **kwargs)
  File "/home/gene/Desktop/CRM/app/routes.py", line 127, in recentsales
    tot_sales = view_closed_deal_prices(current_user)
  File "/home/gene/Desktop/CRM/app/queryfunc.py", line 48, in view_closed_deal_prices
    for price in prices:
TypeError: 'ClosedDeals' object is not iterable
2019-01-24 20:42:09,342 INFO: ReDefined CRM Startup [in /home/gene/Desktop/CRM/app/__init__.py:53]
2019-01-24 20:42:12,227 ERROR: Exception on /recentsales [GET] [in /home/gene/.local/lib/python3.6/site-packages/flask/app.py:1761]
Traceback (most recent call last):
  File "/home/gene/.local/lib/python3.6/site-packages/flask/app.py", line 2292, in wsgi_app
    response = self.full_dispatch_request()
  File "/home/gene/.local/lib/python3.6/site-packages/flask/app.py", line 1815, in full_dispatch_request
    rv = self.handle_user_exception(e)
  File "/home/gene/.local/lib/python3.6/site-packages/flask/app.py", line 1718, in handle_user_exception
    reraise(exc_type, exc_value, tb)
  File "/home/gene/.local/lib/python3.6/site-packages/flask/_compat.py", line 35, in reraise
    raise value
  File "/home/gene/.local/lib/python3.6/site-packages/flask/app.py", line 1813, in full_dispatch_request
    rv = self.dispatch_request()
  File "/home/gene/.local/lib/python3.6/site-packages/flask/app.py", line 1799, in dispatch_request
    return self.view_functions[rule.endpoint](**req.view_args)
  File "/home/gene/.local/lib/python3.6/site-packages/flask_login/utils.py", line 261, in decorated_view
    return func(*args, **kwargs)
  File "/home/gene/Desktop/CRM/app/routes.py", line 127, in recentsales
    all_closed_prices = all_closed_deals.price
AttributeError: 'list' object has no attribute 'price'
2019-01-24 20:43:37,918 INFO: ReDefined CRM Startup [in /home/gene/Desktop/CRM/app/__init__.py:53]
2019-01-24 20:56:29,139 INFO: ReDefined CRM Startup [in /home/gene/Desktop/CRM/app/__init__.py:53]
2019-01-24 20:58:26,621 INFO: ReDefined CRM Startup [in /home/gene/Desktop/CRM/app/__init__.py:53]
2019-01-24 20:59:58,929 INFO: ReDefined CRM Startup [in /home/gene/Desktop/CRM/app/__init__.py:53]
2019-01-24 21:01:39,833 INFO: ReDefined CRM Startup [in /home/gene/Desktop/CRM/app/__init__.py:53]
2019-01-24 21:05:35,375 INFO: ReDefined CRM Startup [in /home/gene/Desktop/CRM/app/__init__.py:53]
2019-01-24 21:06:06,838 ERROR: Exception on /recentsales [GET] [in /home/gene/.local/lib/python3.6/site-packages/flask/app.py:1761]
Traceback (most recent call last):
  File "/home/gene/.local/lib/python3.6/site-packages/flask/app.py", line 2292, in wsgi_app
    response = self.full_dispatch_request()
  File "/home/gene/.local/lib/python3.6/site-packages/flask/app.py", line 1815, in full_dispatch_request
    rv = self.handle_user_exception(e)
  File "/home/gene/.local/lib/python3.6/site-packages/flask/app.py", line 1718, in handle_user_exception
    reraise(exc_type, exc_value, tb)
  File "/home/gene/.local/lib/python3.6/site-packages/flask/_compat.py", line 35, in reraise
    raise value
  File "/home/gene/.local/lib/python3.6/site-packages/flask/app.py", line 1813, in full_dispatch_request
    rv = self.dispatch_request()
  File "/home/gene/.local/lib/python3.6/site-packages/flask/app.py", line 1799, in dispatch_request
    return self.view_functions[rule.endpoint](**req.view_args)
  File "/home/gene/.local/lib/python3.6/site-packages/flask_login/utils.py", line 261, in decorated_view
    return func(*args, **kwargs)
  File "/home/gene/Desktop/CRM/app/routes.py", line 129, in recentsales
    tot_sales = tot_sales + everyone.price
TypeError: unsupported operand type(s) for +: 'int' and 'NoneType'
2019-01-24 21:06:17,658 ERROR: Exception on /recentsales [GET] [in /home/gene/.local/lib/python3.6/site-packages/flask/app.py:1761]
Traceback (most recent call last):
  File "/home/gene/.local/lib/python3.6/site-packages/flask/app.py", line 2292, in wsgi_app
    response = self.full_dispatch_request()
  File "/home/gene/.local/lib/python3.6/site-packages/flask/app.py", line 1815, in full_dispatch_request
    rv = self.handle_user_exception(e)
  File "/home/gene/.local/lib/python3.6/site-packages/flask/app.py", line 1718, in handle_user_exception
    reraise(exc_type, exc_value, tb)
  File "/home/gene/.local/lib/python3.6/site-packages/flask/_compat.py", line 35, in reraise
    raise value
  File "/home/gene/.local/lib/python3.6/site-packages/flask/app.py", line 1813, in full_dispatch_request
    rv = self.dispatch_request()
  File "/home/gene/.local/lib/python3.6/site-packages/flask/app.py", line 1799, in dispatch_request
    return self.view_functions[rule.endpoint](**req.view_args)
  File "/home/gene/.local/lib/python3.6/site-packages/flask_login/utils.py", line 261, in decorated_view
    return func(*args, **kwargs)
  File "/home/gene/Desktop/CRM/app/routes.py", line 129, in recentsales
    tot_sales = tot_sales + everyone.price
TypeError: unsupported operand type(s) for +: 'int' and 'NoneType'
2019-01-24 21:06:28,439 INFO: ReDefined CRM Startup [in /home/gene/Desktop/CRM/app/__init__.py:53]
