2018-12-18 19:58:40,437 ERROR: Exception on /view_people/2 [GET] [in /mnt/c/Users/GM/Desktop/CRM/venv/lib/python3.6/site-packages/flask/app.py:1761]
Traceback (most recent call last):
  File "/mnt/c/Users/GM/Desktop/CRM/venv/lib/python3.6/site-packages/flask/app.py", line 2292, in wsgi_app
    response = self.full_dispatch_request()
  File "/mnt/c/Users/GM/Desktop/CRM/venv/lib/python3.6/site-packages/flask/app.py", line 1815, in full_dispatch_request
    rv = self.handle_user_exception(e)
  File "/mnt/c/Users/GM/Desktop/CRM/venv/lib/python3.6/site-packages/flask/app.py", line 1718, in handle_user_exception
    reraise(exc_type, exc_value, tb)
  File "/mnt/c/Users/GM/Desktop/CRM/venv/lib/python3.6/site-packages/flask/_compat.py", line 35, in reraise
    raise value
  File "/mnt/c/Users/GM/Desktop/CRM/venv/lib/python3.6/site-packages/flask/app.py", line 1813, in full_dispatch_request
    rv = self.dispatch_request()
  File "/mnt/c/Users/GM/Desktop/CRM/venv/lib/python3.6/site-packages/flask/app.py", line 1799, in dispatch_request
    return self.view_functions[rule.endpoint](**req.view_args)
  File "/mnt/c/Users/GM/Desktop/CRM/venv/lib/python3.6/site-packages/flask_login/utils.py", line 261, in decorated_view
    return func(*args, **kwargs)
  File "/mnt/c/Users/GM/Desktop/CRM/app/routes.py", line 97, in view_people
    return render_template('view_people.html', title = 'View Person', select_people=select_people, form=form, notes_form=notes_form, viewpnotes=pnotes)
  File "/mnt/c/Users/GM/Desktop/CRM/venv/lib/python3.6/site-packages/flask/templating.py", line 135, in render_template
    context, ctx.app)
  File "/mnt/c/Users/GM/Desktop/CRM/venv/lib/python3.6/site-packages/flask/templating.py", line 117, in _render
    rv = template.render(context)
  File "/mnt/c/Users/GM/Desktop/CRM/venv/lib/python3.6/site-packages/jinja2/asyncsupport.py", line 76, in render
    return original_render(self, *args, **kwargs)
  File "/mnt/c/Users/GM/Desktop/CRM/venv/lib/python3.6/site-packages/jinja2/environment.py", line 1008, in render
    return self.environment.handle_exception(exc_info, True)
  File "/mnt/c/Users/GM/Desktop/CRM/venv/lib/python3.6/site-packages/jinja2/environment.py", line 780, in handle_exception
    reraise(exc_type, exc_value, tb)
  File "/mnt/c/Users/GM/Desktop/CRM/venv/lib/python3.6/site-packages/jinja2/_compat.py", line 37, in reraise
    raise value.with_traceback(tb)
  File "/mnt/c/Users/GM/Desktop/CRM/app/templates/view_people.html", line 2, in top-level template code
    {% import 'bootstrap/wtf.html' as wtf %}
  File "/mnt/c/Users/GM/Desktop/CRM/app/templates/base.html", line 1, in top-level template code
    {% extends 'bootstrap/base.html' %}
  File "/mnt/c/Users/GM/Desktop/CRM/venv/lib/python3.6/site-packages/flask_bootstrap/templates/bootstrap/base.html", line 1, in top-level template code
    {% block doc -%}
  File "/mnt/c/Users/GM/Desktop/CRM/venv/lib/python3.6/site-packages/flask_bootstrap/templates/bootstrap/base.html", line 4, in block "doc"
    {%- block html %}
  File "/mnt/c/Users/GM/Desktop/CRM/venv/lib/python3.6/site-packages/flask_bootstrap/templates/bootstrap/base.html", line 20, in block "html"
    {% block body -%}
  File "/mnt/c/Users/GM/Desktop/CRM/venv/lib/python3.6/site-packages/flask_bootstrap/templates/bootstrap/base.html", line 23, in block "body"
    {% block content -%}
  File "/mnt/c/Users/GM/Desktop/CRM/app/templates/base.html", line 66, in block "content"
    {% block app_content %}{% endblock %}
  File "/mnt/c/Users/GM/Desktop/CRM/app/templates/view_people.html", line 19, in block "app_content"
    <a href="{{ url_for('hello_pdf', name=name) }}" class="btn btn-success"></a>
  File "/mnt/c/Users/GM/Desktop/CRM/venv/lib/python3.6/site-packages/flask/helpers.py", line 356, in url_for
    return appctx.app.handle_url_build_error(error, endpoint, values)
  File "/mnt/c/Users/GM/Desktop/CRM/venv/lib/python3.6/site-packages/flask/app.py", line 2061, in handle_url_build_error
    reraise(exc_type, exc_value, tb)
  File "/mnt/c/Users/GM/Desktop/CRM/venv/lib/python3.6/site-packages/flask/_compat.py", line 35, in reraise
    raise value
  File "/mnt/c/Users/GM/Desktop/CRM/venv/lib/python3.6/site-packages/flask/helpers.py", line 345, in url_for
    force_external=external)
  File "/mnt/c/Users/GM/Desktop/CRM/venv/lib/python3.6/site-packages/werkzeug/routing.py", line 1776, in build
    raise BuildError(endpoint, values, method, self)
werkzeug.routing.BuildError: Could not build url for endpoint 'hello_pdf' with values ['name']. Did you mean 'seller_prospects' instead?
2018-12-18 20:10:25,687 INFO: ReDefined CRM Startup [in /mnt/c/Users/GM/Desktop/CRM/app/__init__.py:53]
2018-12-18 20:12:10,518 INFO: ReDefined CRM Startup [in /mnt/c/Users/GM/Desktop/CRM/app/__init__.py:53]
2018-12-18 20:12:13,056 ERROR: Exception on /view_people/2 [GET] [in /mnt/c/Users/GM/Desktop/CRM/venv/lib/python3.6/site-packages/flask/app.py:1761]
Traceback (most recent call last):
  File "/mnt/c/Users/GM/Desktop/CRM/venv/lib/python3.6/site-packages/flask/app.py", line 2292, in wsgi_app
    response = self.full_dispatch_request()
  File "/mnt/c/Users/GM/Desktop/CRM/venv/lib/python3.6/site-packages/flask/app.py", line 1815, in full_dispatch_request
    rv = self.handle_user_exception(e)
  File "/mnt/c/Users/GM/Desktop/CRM/venv/lib/python3.6/site-packages/flask/app.py", line 1718, in handle_user_exception
    reraise(exc_type, exc_value, tb)
  File "/mnt/c/Users/GM/Desktop/CRM/venv/lib/python3.6/site-packages/flask/_compat.py", line 35, in reraise
    raise value
  File "/mnt/c/Users/GM/Desktop/CRM/venv/lib/python3.6/site-packages/flask/app.py", line 1813, in full_dispatch_request
    rv = self.dispatch_request()
  File "/mnt/c/Users/GM/Desktop/CRM/venv/lib/python3.6/site-packages/flask/app.py", line 1799, in dispatch_request
    return self.view_functions[rule.endpoint](**req.view_args)
  File "/mnt/c/Users/GM/Desktop/CRM/venv/lib/python3.6/site-packages/flask_login/utils.py", line 261, in decorated_view
    return func(*args, **kwargs)
  File "/mnt/c/Users/GM/Desktop/CRM/app/routes.py", line 101, in view_people
    return render_template('view_people.html', title = 'View Person', select_people=select_people, form=form, notes_form=notes_form, viewpnotes=pnotes)
  File "/mnt/c/Users/GM/Desktop/CRM/venv/lib/python3.6/site-packages/flask/templating.py", line 135, in render_template
    context, ctx.app)
  File "/mnt/c/Users/GM/Desktop/CRM/venv/lib/python3.6/site-packages/flask/templating.py", line 117, in _render
    rv = template.render(context)
  File "/mnt/c/Users/GM/Desktop/CRM/venv/lib/python3.6/site-packages/jinja2/asyncsupport.py", line 76, in render
    return original_render(self, *args, **kwargs)
  File "/mnt/c/Users/GM/Desktop/CRM/venv/lib/python3.6/site-packages/jinja2/environment.py", line 1008, in render
    return self.environment.handle_exception(exc_info, True)
  File "/mnt/c/Users/GM/Desktop/CRM/venv/lib/python3.6/site-packages/jinja2/environment.py", line 780, in handle_exception
    reraise(exc_type, exc_value, tb)
  File "/mnt/c/Users/GM/Desktop/CRM/venv/lib/python3.6/site-packages/jinja2/_compat.py", line 37, in reraise
    raise value.with_traceback(tb)
  File "/mnt/c/Users/GM/Desktop/CRM/app/templates/view_people.html", line 2, in top-level template code
    {% import 'bootstrap/wtf.html' as wtf %}
  File "/mnt/c/Users/GM/Desktop/CRM/app/templates/base.html", line 1, in top-level template code
    {% extends 'bootstrap/base.html' %}
  File "/mnt/c/Users/GM/Desktop/CRM/venv/lib/python3.6/site-packages/flask_bootstrap/templates/bootstrap/base.html", line 1, in top-level template code
    {% block doc -%}
  File "/mnt/c/Users/GM/Desktop/CRM/venv/lib/python3.6/site-packages/flask_bootstrap/templates/bootstrap/base.html", line 4, in block "doc"
    {%- block html %}
  File "/mnt/c/Users/GM/Desktop/CRM/venv/lib/python3.6/site-packages/flask_bootstrap/templates/bootstrap/base.html", line 20, in block "html"
    {% block body -%}
  File "/mnt/c/Users/GM/Desktop/CRM/venv/lib/python3.6/site-packages/flask_bootstrap/templates/bootstrap/base.html", line 23, in block "body"
    {% block content -%}
  File "/mnt/c/Users/GM/Desktop/CRM/app/templates/base.html", line 66, in block "content"
    {% block app_content %}{% endblock %}
  File "/mnt/c/Users/GM/Desktop/CRM/app/templates/view_people.html", line 19, in block "app_content"
    <a href="{{ url_for('hello_pdf', name=name) }}" class="btn btn-success">Print Listing Agreement</a>
  File "/mnt/c/Users/GM/Desktop/CRM/venv/lib/python3.6/site-packages/flask/helpers.py", line 356, in url_for
    return appctx.app.handle_url_build_error(error, endpoint, values)
  File "/mnt/c/Users/GM/Desktop/CRM/venv/lib/python3.6/site-packages/flask/app.py", line 2061, in handle_url_build_error
    reraise(exc_type, exc_value, tb)
  File "/mnt/c/Users/GM/Desktop/CRM/venv/lib/python3.6/site-packages/flask/_compat.py", line 35, in reraise
    raise value
  File "/mnt/c/Users/GM/Desktop/CRM/venv/lib/python3.6/site-packages/flask/helpers.py", line 345, in url_for
    force_external=external)
  File "/mnt/c/Users/GM/Desktop/CRM/venv/lib/python3.6/site-packages/werkzeug/routing.py", line 1776, in build
    raise BuildError(endpoint, values, method, self)
werkzeug.routing.BuildError: Could not build url for endpoint 'hello_pdf' with values ['name']. Did you forget to specify values ['people_id']?
