2018-10-30 20:49:57,571 ERROR: Exception on /search_client [GET] [in /mnt/c/Users/GM/Desktop/CRM/venv/lib/python3.6/site-packages/flask/app.py:1761]
Traceback (most recent call last):
  File "/mnt/c/Users/GM/Desktop/CRM/venv/lib/python3.6/site-packages/flask/app.py", line 2292, in wsgi_app
    response = self.full_dispatch_request()
  File "/mnt/c/Users/GM/Desktop/CRM/venv/lib/python3.6/site-packages/flask/app.py", line 1815, in full_dispatch_request
    rv = self.handle_user_exception(e)
  File "/mnt/c/Users/GM/Desktop/CRM/venv/lib/python3.6/site-packages/flask/app.py", line 1718, in handle_user_exception
    reraise(exc_type, exc_value, tb)
  File "/mnt/c/Users/GM/Desktop/CRM/venv/lib/python3.6/site-packages/flask/_compat.py", line 35, in reraise
    raise value
  File "/mnt/c/Users/GM/Desktop/CRM/venv/lib/python3.6/site-packages/flask/app.py", line 1813, in full_dispatch_request
    rv = self.dispatch_request()
  File "/mnt/c/Users/GM/Desktop/CRM/venv/lib/python3.6/site-packages/flask/app.py", line 1799, in dispatch_request
    return self.view_functions[rule.endpoint](**req.view_args)
  File "/mnt/c/Users/GM/Desktop/CRM/venv/lib/python3.6/site-packages/flask_login/utils.py", line 261, in decorated_view
    return func(*args, **kwargs)
  File "/mnt/c/Users/GM/Desktop/CRM/app/routes.py", line 56, in search_client
    return render_template("search_client.html", title='Search for Prospect/Client', form=form)
  File "/mnt/c/Users/GM/Desktop/CRM/venv/lib/python3.6/site-packages/flask/templating.py", line 135, in render_template
    context, ctx.app)
  File "/mnt/c/Users/GM/Desktop/CRM/venv/lib/python3.6/site-packages/flask/templating.py", line 117, in _render
    rv = template.render(context)
  File "/mnt/c/Users/GM/Desktop/CRM/venv/lib/python3.6/site-packages/jinja2/asyncsupport.py", line 76, in render
    return original_render(self, *args, **kwargs)
  File "/mnt/c/Users/GM/Desktop/CRM/venv/lib/python3.6/site-packages/jinja2/environment.py", line 1008, in render
    return self.environment.handle_exception(exc_info, True)
  File "/mnt/c/Users/GM/Desktop/CRM/venv/lib/python3.6/site-packages/jinja2/environment.py", line 780, in handle_exception
    reraise(exc_type, exc_value, tb)
  File "/mnt/c/Users/GM/Desktop/CRM/venv/lib/python3.6/site-packages/jinja2/_compat.py", line 37, in reraise
    raise value.with_traceback(tb)
  File "/mnt/c/Users/GM/Desktop/CRM/app/templates/search_client.html", line 2, in top-level template code
    {% import 'bootstrap/wtf.html' as wtf %}
  File "/mnt/c/Users/GM/Desktop/CRM/app/templates/base.html", line 1, in top-level template code
    {% extends 'bootstrap/base.html' %}
  File "/mnt/c/Users/GM/Desktop/CRM/venv/lib/python3.6/site-packages/flask_bootstrap/templates/bootstrap/base.html", line 1, in top-level template code
    {% block doc -%}
  File "/mnt/c/Users/GM/Desktop/CRM/venv/lib/python3.6/site-packages/flask_bootstrap/templates/bootstrap/base.html", line 4, in block "doc"
    {%- block html %}
  File "/mnt/c/Users/GM/Desktop/CRM/venv/lib/python3.6/site-packages/flask_bootstrap/templates/bootstrap/base.html", line 20, in block "html"
    {% block body -%}
  File "/mnt/c/Users/GM/Desktop/CRM/venv/lib/python3.6/site-packages/flask_bootstrap/templates/bootstrap/base.html", line 21, in block "body"
    {% block navbar %}
  File "/mnt/c/Users/GM/Desktop/CRM/app/templates/base.html", line 35, in block "navbar"
    <form class="navbar-form navbar-left" action="{{ url_for('/search_client/av') }}">
  File "/mnt/c/Users/GM/Desktop/CRM/venv/lib/python3.6/site-packages/flask/helpers.py", line 356, in url_for
    return appctx.app.handle_url_build_error(error, endpoint, values)
  File "/mnt/c/Users/GM/Desktop/CRM/venv/lib/python3.6/site-packages/flask/app.py", line 2061, in handle_url_build_error
    reraise(exc_type, exc_value, tb)
  File "/mnt/c/Users/GM/Desktop/CRM/venv/lib/python3.6/site-packages/flask/_compat.py", line 35, in reraise
    raise value
  File "/mnt/c/Users/GM/Desktop/CRM/venv/lib/python3.6/site-packages/flask/helpers.py", line 345, in url_for
    force_external=external)
  File "/mnt/c/Users/GM/Desktop/CRM/venv/lib/python3.6/site-packages/werkzeug/routing.py", line 1776, in build
    raise BuildError(endpoint, values, method, self)
werkzeug.routing.BuildError: Could not build url for endpoint '/search_client/av'. Did you mean 'search_client' instead?
2018-10-30 20:50:18,561 INFO: ReDefined CRM Startup [in /mnt/c/Users/GM/Desktop/CRM/app/__init__.py:53]
2018-10-30 20:50:54,414 INFO: ReDefined CRM Startup [in /mnt/c/Users/GM/Desktop/CRM/app/__init__.py:53]
2018-10-30 20:54:10,096 INFO: ReDefined CRM Startup [in /mnt/c/Users/GM/Desktop/CRM/app/__init__.py:53]
2018-10-30 20:55:56,624 INFO: ReDefined CRM Startup [in /mnt/c/Users/GM/Desktop/CRM/app/__init__.py:53]
2018-10-30 20:57:24,966 INFO: ReDefined CRM Startup [in /mnt/c/Users/GM/Desktop/CRM/app/__init__.py:53]
2018-10-30 20:57:55,973 INFO: ReDefined CRM Startup [in /mnt/c/Users/GM/Desktop/CRM/app/__init__.py:53]
2018-10-30 21:03:25,747 INFO: ReDefined CRM Startup [in /mnt/c/Users/GM/Desktop/CRM/app/__init__.py:53]
2018-11-01 18:22:07,896 INFO: ReDefined CRM Startup [in /mnt/c/Users/GM/Desktop/CRM/app/__init__.py:53]
2018-11-01 18:30:11,810 INFO: ReDefined CRM Startup [in /mnt/c/Users/GM/Desktop/CRM/app/__init__.py:53]
2018-11-01 18:58:38,424 INFO: ReDefined CRM Startup [in /mnt/c/Users/GM/Desktop/CRM/app/__init__.py:53]
2018-11-01 19:00:46,082 INFO: ReDefined CRM Startup [in /mnt/c/Users/GM/Desktop/CRM/app/__init__.py:53]
2018-11-01 19:01:59,409 INFO: ReDefined CRM Startup [in /mnt/c/Users/GM/Desktop/CRM/app/__init__.py:53]
2018-11-01 19:32:09,697 INFO: ReDefined CRM Startup [in /mnt/c/Users/GM/Desktop/CRM/app/__init__.py:53]
2018-11-01 19:32:17,735 INFO: ReDefined CRM Startup [in /mnt/c/Users/GM/Desktop/CRM/app/__init__.py:53]
2018-11-01 19:33:14,727 INFO: ReDefined CRM Startup [in /mnt/c/Users/GM/Desktop/CRM/app/__init__.py:53]
2018-11-01 19:37:20,646 INFO: ReDefined CRM Startup [in /mnt/c/Users/GM/Desktop/CRM/app/__init__.py:53]
2018-11-01 19:37:24,605 INFO: ReDefined CRM Startup [in /mnt/c/Users/GM/Desktop/CRM/app/__init__.py:53]
2018-11-01 19:50:04,650 INFO: ReDefined CRM Startup [in /mnt/c/Users/GM/Desktop/CRM/app/__init__.py:53]
